Workbook

Sheet toAdd
A1: Current Players to Add | E1: Calculator | F1: =E2+F2 -> 56
A2: Players will be added at 100 Games | E2: 51 | F2: 5
A4: 2025: Top | D4: Jungle | G4: Mid | J4: Adc | M4: Support
A5: Player | B5: Games | D5: Player | E5: Games | G5: Player | H5: Games | J5: Player | K5: Games | M5: Player | N5: Games
A6: Rich | B6: 97 | D6: HamBak | E6: 56 | G6: Ucal | J6: Diable
G7: Calix
G8: Fisher

Sheet Top
A1: Top | B1: 2022 | C1: Games: | D1: 686 | G1: 2023 | H1: Games: | I1: 688 | L1: 2024 | M1: Games: | N1: 679 | Q1: 2025 | R1: Games: | S1: 754 | V1: 2026 | W1: Games: | X1: 125
A2: Champion | B2: Picks | C2: Total | D2: Bans | E2: Wins | G2: Picks | H2: Total | I2: Bans | J2: Wins | L2: Picks | M2: Total | N2: Bans | O2: Wins | Q2: Picks | R2: Total | S2: Bans | T2: Wins | V2: Picks | W2: Total | X2: Bans | Y2: Wins | AA2: Total Picks | AB2: Pickrate | AC2: Winrate
A3: Renekton | B3: 64 | C3: 67 | D3: 156 | E3: 28 | G3: 215 | H3: 216 | I3: 208 | J3: 103 | L3: 119 | M3: 121 | N3: 141 | O3: 45 | Q3: 85 | R3: 87 | S3: 79 | T3: 53 | V3: 28 | W3: 28 | X3: 18 | Y3: 14 | AA3: =B3+G3+L3+Q3+V3 -> 511 | AB3: =(AA3+(B3/C3*D3+G3/H3*I3+L3/M3*N3+Q3/R3*S3+V3/W3*X3))/($D$1+$I$1+$N$1+$S$1+$X$1) -> 0.37547929 | AC3: =(E3+J3+O3+T3+Y3)/(AA3) -> 0.47553816
A4: K'Sante | C4: 1 | G4: 245 | H4: 269 | I4: 192 | J4: 115 | L4: 278 | M4: 279 | N4: 154 | O4: 149 | Q4: 120 | R4: 120 | S4: 60 | T4: 50 | V4: 25 | W4: 25 | X4: 14 | Y4: 14 | AA4: =B4+G4+L4+Q4+V4 -> 668 | AB4: =(AA4+(B4/C4*D4+G4/H4*I4+L4/M4*N4+Q4/R4*S4+V4/W4*X4))/($D$1+$I$1+$N$1+$S$1+$X$1) -> 0.36504704 | AC4: =(E4+J4+O4+T4+Y4)/(AA4) -> 0.49101796
A5: Rumble | B5: 6 | C5: 7 | D5: 1 | E5: 2 | G5: 45 | H5: 48 | I5: 104 | J5: 26 | L5: 109 | M5: 121 | N5: 314 | O5: 64 | Q5: 211 | R5: 211 | S5: 171 | T5: 106 | V5: 19 | W5: 19 | X5: 75 | Y5: 10 | AA5: =B5+G5+L5+Q5+V5 -> 390 | AB5: =(AA5+(B5/C5*D5+G5/H5*I5+L5/M5*N5+Q5/R5*S5+V5/W5*X5))/($D$1+$I$1+$N$1+$S$1+$X$1) -> 0.3469361 | AC5: =(E5+J5+O5+T5+Y5)/(AA5) -> 0.53333333
A6: Gwen | B6: 189 | C6: 194 | D6: 173 | E6: 84 | G6: 32 | H6: 32 | I6: 36 | J6: 14 | L6: 17 | M6: 17 | N6: 3 | O6: 6 | Q6: 121 | R6: 121 | S6: 197 | T6: 67 | V6: 22 | W6: 22 | X6: 30 | Y6: 16 | AA6: =B6+G6+L6+Q6+V6 -> 381 | AB6: =(AA6+(B6/C6*D6+G6/H6*I6+L6/M6*N6+Q6/R6*S6+V6/W6*X6))/($D$1+$I$1+$N$1+$S$1+$X$1) -> 0.27815185 | AC6: =(E6+J6+O6+T6+Y6)/(AA6) -> 0.49081365
A7: Gnar | B7: 188 | C7: 188 | D7: 75 | E7: 93 | G7: 129 | H7: 129 | I7: 70 | J7: 76 | L7: 141 | M7: 141 | N7: 74 | O7: 71 | Q7: 50 | R7: 50 | S7: 34 | T7: 22 | V7: 23 | W7: 23 | X7: 15 | Y7: 13 | AA7: =B7+G7+L7+Q7+V7 -> 531 | AB7: =(AA7+(B7/C7*D7+G7/H7*I7+L7/M7*N7+Q7/R7*S7+V7/W7*X7))/($D$1+$I$1+$N$1+$S$1+$X$1) -> 0.27251023 | AC7: =(E7+J7+O7+T7+Y7)/(AA7) -> 0.51789077
A8: Jax | B8: 36 | C8: 36 | D8: 25 | E8: 19 | G8: 188 | H8: 189 | I8: 185 | J8: 93 | L8: 103 | M8: 121 | N8: 105 | O8: 45 | Q8: 76 | R8: 78 | S8: 55 | T8: 39 | V8: 9 | W8: 11 | X8: 8 | Y8: 3 | AA8: =B8+G8+L8+Q8+V8 -> 412 | AB8: =(AA8+(B8/C8*D8+G8/H8*I8+L8/M8*N8+Q8/R8*S8+V8/W8*X8))/($D$1+$I$1+$N$1+$S$1+$X$1) -> 0.26280236 | AC8: =(E8+J8+O8+T8+Y8)/(AA8) -> 0.48300971
A9: Jayce | B9: 64 | C9: 66 | D9: 91 | E9: 40 | G9: 57 | H9: 143 | I9: 154 | J9: 32 | L9: 18 | M9: 29 | N9: 38 | O9: 10 | Q9: 115 | R9: 126 | S9: 118 | T9: 56 | V9: 5 | W9: 11 | X9: 74 | Y9: 2 | AA9: =B9+G9+L9+Q9+V9 -> 259 | AB9: =(AA9+(B9/C9*D9+G9/H9*I9+L9/M9*N9+Q9/R9*S9+V9/W9*X9))/($D$1+$I$1+$N$1+$S$1+$X$1) -> 0.19561665 | AC9: =(E9+J9+O9+T9+Y9)/(AA9) -> 0.54054054
A10: Aatrox | B10: 81 | C10: 82 | D10: 91 | E10: 48 | G10: 61 | H10: 61 | I10: 24 | J10: 27 | L10: 111 | M10: 111 | N10: 40 | O10: 54 | Q10: 68 | R10: 68 | S10: 19 | T10: 35 | V10: 5 | W10: 14 | X10: 1 | Y10: 2 | AA10: =B10+G10+L10+Q10+V10 -> 326 | AB10: =(AA10+(B10/C10*D10+G10/H10*I10+L10/M10*N10+Q10/R10*S10+V10/W10*X10))/($D$1+$I$1+$N$1+$S$1+$X$1) -> 0.17027537 | AC10: =(E10+J10+O10+T10+Y10)/(AA10) -> 0.50920245
A11: Ornn | B11: 94 | C11: 97 | D11: 100 | E11: 49 | G11: 39 | H11: 39 | I11: 14 | J11: 17 | L11: 16 | M11: 41 | N11: 6 | O11: 9 | Q11: 59 | R11: 60 | S11: 44 | T11: 33 | V11: 6 | W11: 6 | X11: 1 | Y11: 2 | AA11: =B11+G11+L11+Q11+V11 -> 214 | AB11: =(AA11+(B11/C11*D11+G11/H11*I11+L11/M11*N11+Q11/R11*S11+V11/W11*X11))/($D$1+$I$1+$N$1+$S$1+$X$1) -> 0.12671055 | AC11: =(E11+J11+O11+T11+Y11)/(AA11) -> 0.51401869
A12: Sion | B12: 18 | C12: 20 | D12: 2 | E12: 8 | G12: 59 | H12: 63 | I12: 30 | J12: 29 | L12: 4 | M12: 7 | N12: 0 | O12: 1 | Q12: 127 | R12: 127 | S12: 88 | T12: 67 | V12: 27 | W12: 27 | X12: 7 | Y12: 6 | AA12: =B12+G12+L12+Q12+V12 -> 235 | AB12: =(AA12+(B12/C12*D12+G12/H12*I12+L12/M12*N12+Q12/R12*S12+V12/W12*X12))/($D$1+$I$1+$N$1+$S$1+$X$1) -> 0.12274735 | AC12: =(E12+J12+O12+T12+Y12)/(AA12) -> 0.47234043
A13: Ambessa | C13: 1 | H13: 1 | M13: 1 | Q13: 172 | R13: 176 | S13: 127 | T13: 67 | V13: 20 | W13: 31 | X13: 33 | Y13: 10 | AA13: =B13+G13+L13+Q13+V13 -> 192 | AB13: =(AA13+(B13/C13*D13+G13/H13*I13+L13/M13*N13+Q13/R13*S13+V13/W13*X13))/($D$1+$I$1+$N$1+$S$1+$X$1) -> 0.11507638 | AC13: =(E13+J13+O13+T13+Y13)/(AA13) -> 0.40104167
A14: Gragas | B14: 99 | C14: 108 | D14: 38 | E14: 53 | G14: 80 | H14: 118 | I14: 77 | J14: 46 | L14: 12 | M14: 15 | N14: 3 | O14: 9 | Q14: 23 | R14: 32 | S14: 12 | T14: 11 | V14: 2 | W14: 2 | X14: 0 | Y14: 0 | AA14: =B14+G14+L14+Q14+V14 -> 216 | AB14: =(AA14+(B14/C14*D14+G14/H14*I14+L14/M14*N14+Q14/R14*S14+V14/W14*X14))/($D$1+$I$1+$N$1+$S$1+$X$1) -> 0.10711519 | AC14: =(E14+J14+O14+T14+Y14)/(AA14) -> 0.55092593
A15: Kennen | B15: 28 | C15: 28 | D15: 18 | E15: 12 | G15: 32 | H15: 32 | I15: 73 | J15: 14 | L15: 39 | M15: 39 | N15: 20 | O15: 16 | Q15: 10 | R15: 10 | S15: 3 | T15: 5 | V15: 12 | W15: 12 | X15: 15 | Y15: 7 | AA15: =B15+G15+L15+Q15+V15 -> 121 | AB15: =(AA15+(B15/C15*D15+G15/H15*I15+L15/M15*N15+Q15/R15*S15+V15/W15*X15))/($D$1+$I$1+$N$1+$S$1+$X$1) -> 0.08526603 | AC15: =(E15+J15+O15+T15+Y15)/(AA15) -> 0.44628099
A16: Camille | B16: 57 | C16: 58 | D16: 44 | E16: 33 | G16: 15 | H16: 15 | I16: 7 | J16: 6 | L16: 34 | M16: 38 | N16: 26 | O16: 19 | Q16: 31 | R16: 34 | S16: 18 | T16: 23 | W16: 1 | AA16: =B16+G16+L16+Q16+V16 -> 137 | AB16: =(AA16+(B16/C16*D16+G16/H16*I16+L16/M16*N16+Q16/R16*S16+V16/W16*X16))/($D$1+$I$1+$N$1+$S$1+$X$1) -> 0.077393009 | AC16: =(E16+J16+O16+T16+Y16)/(AA16) -> 0.59124088
A17: Gankplank | B17: 85 | C17: 85 | D17: 88 | E17: 48 | G17: 11 | H17: 11 | I17: 4 | J17: 9 | L17: 12 | M17: 12 | N17: 7 | O17: 9 | Q17: 12 | R17: 12 | S17: 3 | T17: 6 | W17: 1 | AA17: =B17+G17+L17+Q17+V17 -> 120 | AB17: =(AA17+(B17/C17*D17+G17/H17*I17+L17/M17*N17+Q17/R17*S17+V17/W17*X17))/($D$1+$I$1+$N$1+$S$1+$X$1) -> 0.075716235 | AC17: =(E17+J17+O17+T17+Y17)/(AA17) -> 0.6
A18: Aurora | C18: 1 | H18: 1 | L18: 18 | M18: 32 | N18: 95 | O18: 12 | Q18: 50 | R18: 147 | S18: 133 | T18: 28 | V18: 9 | W18: 24 | X18: 16 | Y18: 3 | AA18: =B18+G18+L18+Q18+V18 -> 77 | AB18: =(AA18+(B18/C18*D18+G18/H18*I18+L18/M18*N18+Q18/R18*S18+V18/W18*X18))/($D$1+$I$1+$N$1+$S$1+$X$1) -> 0.061963027 | AC18: =(E18+J18+O18+T18+Y18)/(AA18) -> 0.55844156
A19: Poppy | B19: 1 | C19: 104 | D19: 163 | E19: 0 | G19: 29 | H19: 84 | I19: 196 | J19: 17 | L19: 23 | M19: 118 | N19: 148 | O19: 7 | Q19: 7 | R19: 133 | S19: 301 | T19: 4 | W19: 1 | AA19: =B19+G19+L19+Q19+V19 -> 60 | AB19: =(AA19+(B19/C19*D19+G19/H19*I19+L19/M19*N19+Q19/R19*S19+V19/W19*X19))/($D$1+$I$1+$N$1+$S$1+$X$1) -> 0.059319078 | AC19: =(E19+J19+O19+T19+Y19)/(AA19) -> 0.46666667
A20: Fiora | B20: 41 | C20: 41 | D20: 34 | E20: 23 | G20: 39 | H20: 40 | I20: 38 | J20: 21 | M20: 1 | Q20: 4 | R20: 4 | S20: 0 | T20: 2 | W20: 1 | AA20: =B20+G20+L20+Q20+V20 -> 84 | AB20: =(AA20+(B20/C20*D20+G20/H20*I20+L20/M20*N20+Q20/R20*S20+V20/W20*X20))/($D$1+$I$1+$N$1+$S$1+$X$1) -> 0.052881992 | AC20: =(E20+J20+O20+T20+Y20)/(AA20) -> 0.54761905
A21: Twisted Fate | C21: 1 | H21: 1 | L21: 48 | M21: 54 | N21: 107 | O21: 32 | R21: 1 | W21: 1 | AA21: =B21+G21+L21+Q21+V21 -> 48 | AB21: =(AA21+(B21/C21*D21+G21/H21*I21+L21/M21*N21+Q21/R21*S21+V21/W21*X21))/($D$1+$I$1+$N$1+$S$1+$X$1) -> 0.048810065 | AC21: =(E21+J21+O21+T21+Y21)/(AA21) -> 0.66666667
A22: Sejuani | B22: 69 | C22: 123 | D22: 97 | E22: 34 | G22: 5 | H22: 258 | I22: 221 | J22: 2 | M22: 1 | R22: 1 | W22: 1 | AA22: =B22+G22+L22+Q22+V22 -> 74 | AB22: =(AA22+(B22/C22*D22+G22/H22*I22+L22/M22*N22+Q22/R22*S22+V22/W22*X22))/($D$1+$I$1+$N$1+$S$1+$X$1) -> 0.045258383 | AC22: =(E22+J22+O22+T22+Y22)/(AA22) -> 0.48648649
A23: Tryndamere | B23: 46 | C23: 51 | D23: 96 | E23: 20 | H23: 1 | M23: 1 | R23: 1 | W23: 1 | AA23: =B23+G23+L23+Q23+V23 -> 46 | AB23: =(AA23+(B23/C23*D23+G23/H23*I23+L23/M23*N23+Q23/R23*S23+V23/W23*X23))/($D$1+$I$1+$N$1+$S$1+$X$1) -> 0.04522109 | AC23: =(E23+J23+O23+T23+Y23)/(AA23) -> 0.43478261
A24: Udyr | C24: 1 | H24: 1 | L24: 63 | M24: 63 | N24: 46 | O24: 26 | Q24: 1 | R24: 1 | S24: 0 | T24: 0 | W24: 1 | AA24: =B24+G24+L24+Q24+V24 -> 64 | AB24: =(AA24+(B24/C24*D24+G24/H24*I24+L24/M24*N24+Q24/R24*S24+V24/W24*X24))/($D$1+$I$1+$N$1+$S$1+$X$1) -> 0.037517053 | AC24: =(E24+J24+O24+T24+Y24)/(AA24) -> 0.40625
A25: Yorick | C25: 1 | H25: 1 | M25: 1 | Q25: 61 | R25: 61 | S25: 38 | T25: 25 | V25: 3 | W25: 3 | X25: 4 | Y25: 1 | AA25: =B25+G25+L25+Q25+V25 -> 64 | AB25: =(AA25+(B25/C25*D25+G25/H25*I25+L25/M25*N25+Q25/R25*S25+V25/W25*X25))/($D$1+$I$1+$N$1+$S$1+$X$1) -> 0.036152797 | AC25: =(E25+J25+O25+T25+Y25)/(AA25) -> 0.40625
A26: Akali | B26: 39 | C26: 108 | D26: 141 | E26: 23 | G26: 2 | H26: 68 | I26: 85 | J26: 0 | L26: 1 | M26: 37 | N26: 25 | O26: 0 | Q26: 2 | R26: 35 | S26: 36 | T26: 1 | V26: 1 | W26: 11 | X26: 21 | Y26: 1 | AA26: =B26+G26+L26+Q26+V26 -> 45 | AB26: =(AA26+(B26/C26*D26+G26/H26*I26+L26/M26*N26+Q26/R26*S26+V26/W26*X26))/($D$1+$I$1+$N$1+$S$1+$X$1) -> 0.035149583 | AC26: =(E26+J26+O26+T26+Y26)/(AA26) -> 0.55555556
A27: Graves | B27: 48 | C27: 111 | D27: 114 | E27: 26 | G27: 1 | H27: 3 | I27: 0 | J27: 1 | M27: 1 | R27: 1 | W27: 1 | AA27: =B27+G27+L27+Q27+V27 -> 49 | AB27: =(AA27+(B27/C27*D27+G27/H27*I27+L27/M27*N27+Q27/R27*S27+V27/W27*X27))/($D$1+$I$1+$N$1+$S$1+$X$1) -> 0.033525681 | AC27: =(E27+J27+O27+T27+Y27)/(AA27) -> 0.55102041
A28: Skarner | C28: 1 | H28: 1 | L28: 47 | M28: 97 | N28: 82 | O28: 26 | R28: 1 | W28: 1 | AA28: =B28+G28+L28+Q28+V28 -> 47 | AB28: =(AA28+(B28/C28*D28+G28/H28*I28+L28/M28*N28+Q28/R28*S28+V28/W28*X28))/($D$1+$I$1+$N$1+$S$1+$X$1) -> 0.029581159 | AC28: =(E28+J28+O28+T28+Y28)/(AA28) -> 0.55319149
A29: Malphite | B29: 5 | C29: 5 | D29: 5 | E29: 2 | G29: 25 | H29: 25 | I29: 35 | J29: 7 | L29: 6 | M29: 6 | N29: 1 | O29: 2 | R29: 1 | W29: 1 | AA29: =B29+G29+L29+Q29+V29 -> 36 | AB29: =(AA29+(B29/C29*D29+G29/H29*I29+L29/M29*N29+Q29/R29*S29+V29/W29*X29))/($D$1+$I$1+$N$1+$S$1+$X$1) -> 0.026261937 | AC29: =(E29+J29+O29+T29+Y29)/(AA29) -> 0.30555556
A30: Rek'Sai | C30: 1 | H30: 1 | L30: 15 | M30: 21 | N30: 23 | O30: 6 | Q30: 18 | R30: 18 | S30: 4 | T30: 9 | V30: 16 | W30: 16 | X30: 6 | Y30: 8 | AA30: =B30+G30+L30+Q30+V30 -> 49 | AB30: =(AA30+(B30/C30*D30+G30/H30*I30+L30/M30*N30+Q30/R30*S30+V30/W30*X30))/($D$1+$I$1+$N$1+$S$1+$X$1) -> 0.025725979 | AC30: =(E30+J30+O30+T30+Y30)/(AA30) -> 0.46938776
A31: Olaf | B31: 4 | C31: 8 | D31: 8 | E31: 1 | G31: 7 | H31: 8 | I31: 30 | J31: 3 | L31: 10 | M31: 10 | N31: 12 | O31: 6 | Q31: 5 | R31: 7 | S31: 4 | T31: 3 | V31: 2 | W31: 3 | X31: 1 | Y31: 2 | AA31: =B31+G31+L31+Q31+V31 -> 28 | AB31: =(AA31+(B31/C31*D31+G31/H31*I31+L31/M31*N31+Q31/R31*S31+V31/W31*X31))/($D$1+$I$1+$N$1+$S$1+$X$1) -> 0.025161599 | AC31: =(E31+J31+O31+T31+Y31)/(AA31) -> 0.53571429
A32: Yone | B32: 10 | C32: 22 | D32: 16 | E32: 9 | G32: 5 | H32: 50 | I32: 59 | J32: 3 | L32: 12 | M32: 121 | N32: 132 | O32: 8 | R32: 1 | W32: 1 | AA32: =B32+G32+L32+Q32+V32 -> 27 | AB32: =(AA32+(B32/C32*D32+G32/H32*I32+L32/M32*N32+Q32/R32*S32+V32/W32*X32))/($D$1+$I$1+$N$1+$S$1+$X$1) -> 0.018166315 | AC32: =(E32+J32+O32+T32+Y32)/(AA32) -> 0.74074074
A33: Maokai | B33: 15 | C33: 43 | D33: 48 | E33: 4 | G33: 2 | H33: 196 | I33: 282 | J33: 1 | L33: 2 | M33: 154 | N33: 207 | O33: 0 | R33: 1 | W33: 1 | AA33: =B33+G33+L33+Q33+V33 -> 19 | AB33: =(AA33+(B33/C33*D33+G33/H33*I33+L33/M33*N33+Q33/R33*S33+V33/W33*X33))/($D$1+$I$1+$N$1+$S$1+$X$1) -> 0.014089375 | AC33: =(E33+J33+O33+T33+Y33)/(AA33) -> 0.26315789
A34: Irelia | B34: 10 | C34: 14 | D34: 21 | E34: 4 | G34: 5 | H34: 10 | I34: 11 | J34: 0 | L34: 1 | M34: 2 | N34: 3 | O34: 0 | Q34: 2 | R34: 2 | S34: 0 | T34: 1 | W34: 1 | AA34: =B34+G34+L34+Q34+V34 -> 18 | AB34: =(AA34+(B34/C34*D34+G34/H34*I34+L34/M34*N34+Q34/R34*S34+V34/W34*X34))/($D$1+$I$1+$N$1+$S$1+$X$1) -> 0.013642565 | AC34: =(E34+J34+O34+T34+Y34)/(AA34) -> 0.27777778
A35: Galio | C35: 1 | H35: 1 | L35: 5 | M35: 12 | N35: 3 | O35: 3 | Q35: 19 | R35: 113 | S35: 70 | T35: 12 | W35: 1 | AA35: =B35+G35+L35+Q35+V35 -> 24 | AB35: =(AA35+(B35/C35*D35+G35/H35*I35+L35/M35*N35+Q35/R35*S35+V35/W35*X35))/($D$1+$I$1+$N$1+$S$1+$X$1) -> 0.012626164 | AC35: =(E35+J35+O35+T35+Y35)/(AA35) -> 0.625
A36: Vayne | B36: 2 | C36: 6 | D36: 0 | E36: 1 | H36: 1 | L36: 14 | M36: 15 | N36: 21 | O36: 11 | Q36: 1 | R36: 4 | S36: 0 | T36: 0 | W36: 1 | AA36: =B36+G36+L36+Q36+V36 -> 17 | AB36: =(AA36+(B36/C36*D36+G36/H36*I36+L36/M36*N36+Q36/R36*S36+V36/W36*X36))/($D$1+$I$1+$N$1+$S$1+$X$1) -> 0.012482947 | AC36: =(E36+J36+O36+T36+Y36)/(AA36) -> 0.70588235
A37: Mordekaiser | B37: 7 | C37: 7 | D37: 6 | E37: 2 | H37: 1 | L37: 5 | M37: 5 | N37: 4 | O37: 2 | Q37: 10 | R37: 10 | S37: 2 | T37: 3 | W37: 1 | AA37: =B37+G37+L37+Q37+V37 -> 22 | AB37: =(AA37+(B37/C37*D37+G37/H37*I37+L37/M37*N37+Q37/R37*S37+V37/W37*X37))/($D$1+$I$1+$N$1+$S$1+$X$1) -> 0.01159618 | AC37: =(E37+J37+O37+T37+Y37)/(AA37) -> 0.31818182
A38: Urgot | B38: 5 | C38: 5 | D38: 4 | E38: 0 | G38: 2 | H38: 2 | I38: 1 | J38: 1 | L38: 15 | M38: 15 | N38: 5 | O38: 5 | Q38: 2 | R38: 2 | S38: 0 | T38: 0 | W38: 1 | AA38: =B38+G38+L38+Q38+V38 -> 24 | AB38: =(AA38+(B38/C38*D38+G38/H38*I38+L38/M38*N38+Q38/R38*S38+V38/W38*X38))/($D$1+$I$1+$N$1+$S$1+$X$1) -> 0.01159618 | AC38: =(E38+J38+O38+T38+Y38)/(AA38) -> 0.25
A39: Zac | B39: 1 | C39: 4 | D39: 1 | E39: 1 | H39: 1 | L39: 17 | M39: 22 | N39: 19 | O39: 7 | R39: 1 | W39: 1 | AA39: =B39+G39+L39+Q39+V39 -> 18 | AB39: =(AA39+(B39/C39*D39+G39/H39*I39+L39/M39*N39+Q39/R39*S39+V39/W39*X39))/($D$1+$I$1+$N$1+$S$1+$X$1) -> 0.011231862 | AC39: =(E39+J39+O39+T39+Y39)/(AA39) -> 0.44444444
A40: Darius | B40: 2 | C40: 2 | D40: 1 | E40: 0 | G40: 7 | H40: 7 | I40: 14 | J40: 4 | L40: 5 | M40: 5 | N40: 1 | O40: 2 | R40: 1 | W40: 1 | AA40: =B40+G40+L40+Q40+V40 -> 14 | AB40: =(AA40+(B40/C40*D40+G40/H40*I40+L40/M40*N40+Q40/R40*S40+V40/W40*X40))/($D$1+$I$1+$N$1+$S$1+$X$1) -> 0.010231924 | AC40: =(E40+J40+O40+T40+Y40)/(AA40) -> 0.42857143
...

Sheet Jungle
A1: Jungle | B1: 2022 | C1: Games: | D1: 686 | G1: 2023 | H1: Games: | I1: 688 | L1: 2024 | M1: Games: | N1: 679 | Q1: 2025 | R1: Games: | S1: 754 | V1: 2026 | W1: Games: | X1: 125
A2: Champion | B2: Picks | C2: Total | D2: Bans | E2: Wins | G2: Picks | H2: Total | I2: Bans | J2: Wins | L2: Picks | M2: Total | N2: Bans | O2: Wins | Q2: Picks | R2: Total | S2: Bans | T2: Wins | V2: Picks | W2: Total | X2: Bans | Y2: Wins | AA2: Total Picks | AB2: Pickrate | AC2: Winrate
A3: Vi | B3: 63 | C3: 63 | D3: 56 | E3: 30 | G3: 183 | H3: 183 | I3: 293 | J3: 87 | L3: 155 | M3: 155 | N3: 308 | O3: 80 | Q3: 128 | R3: 128 | S3: 354 | T3: 57 | V3: 27 | W3: 27 | X3: 40 | Y3: 14 | AA3: =B3+G3+L3+Q3+V3 -> 556 | AB3: =(AA3+(B3/C3*D3+G3/H3*I3+L3/M3*N3+Q3/R3*S3+V3/W3*X3))/($D$1+$I$1+$N$1+$S$1+$X$1) -> 0.54809004 | AC3: =(E3+J3+O3+T3+Y3)/(AA3) -> 0.48201439
A4: Sejuani | B4: 51 | C4: 123 | D4: 97 | E4: 27 | G4: 253 | H4: 258 | I4: 221 | J4: 118 | L4: 223 | M4: 226 | N4: 209 | O4: 106 | Q4: 103 | R4: 103 | S4: 91 | T4: 43 | V4: 5 | W4: 5 | X4: 1 | Y4: 0 | AA4: =B4+G4+L4+Q4+V4 -> 635 | AB4: =(AA4+(B4/C4*D4+G4/H4*I4+L4/M4*N4+Q4/R4*S4+V4/W4*X4))/($D$1+$I$1+$N$1+$S$1+$X$1) -> 0.40592163 | AC4: =(E4+J4+O4+T4+Y4)/(AA4) -> 0.46299213
A5: Wukong | B5: 146 | C5: 147 | D5: 138 | E5: 73 | G5: 173 | H5: 173 | I5: 104 | J5: 82 | L5: 32 | M5: 32 | N5: 26 | O5: 15 | Q5: 175 | R5: 175 | S5: 111 | T5: 97 | V5: 28 | W5: 28 | X5: 10 | Y5: 13 | AA5: =B5+G5+L5+Q5+V5 -> 554 | AB5: =(AA5+(B5/C5*D5+G5/H5*I5+L5/M5*N5+Q5/R5*S5+V5/W5*X5))/($D$1+$I$1+$N$1+$S$1+$X$1) -> 0.32130328 | AC5: =(E5+J5+O5+T5+Y5)/(AA5) -> 0.50541516
A6: Maokai | B6: 26 | C6: 43 | D6: 48 | E6: 16 | G6: 181 | H6: 196 | I6: 282 | J6: 98 | L6: 141 | M6: 164 | N6: 207 | O6: 80 | Q6: 51 | R6: 60 | S6: 61 | T6: 25 | V6: 2 | W6: 2 | X6: 0 | Y6: 2 | AA6: =B6+G6+L6+Q6+V6 -> 401 | AB6: =(AA6+(B6/C6*D6+G6/H6*I6+L6/M6*N6+Q6/R6*S6+V6/W6*X6))/($D$1+$I$1+$N$1+$S$1+$X$1) -> 0.31386805 | AC6: =(E6+J6+O6+T6+Y6)/(AA6) -> 0.55112219
A7: Lee Sin | B7: 207 | C7: 218 | D7: 112 | E7: 104 | G7: 100 | H7: 101 | I7: 58 | J7: 50 | L7: 96 | M7: 98 | N7: 89 | O7: 44 | Q7: 34 | R7: 35 | S7: 40 | T7: 16 | V7: 8 | W7: 8 | X7: 11 | Y7: 6 | AA7: =B7+G7+L7+Q7+V7 -> 445 | AB7: =(AA7+(B7/C7*D7+G7/H7*I7+L7/M7*N7+Q7/R7*S7+V7/W7*X7))/($D$1+$I$1+$N$1+$S$1+$X$1) -> 0.2543708 | AC7: =(E7+J7+O7+T7+Y7)/(AA7) -> 0.49438202
A8: Poppy | B8: 103 | C8: 104 | D8: 163 | E8: 56 | G8: 55 | H8: 84 | I8: 196 | J8: 28 | L8: 57 | M8: 118 | N8: 148 | O8: 32 | Q8: 46 | R8: 133 | S8: 301 | T8: 26 | V8: 1 | W8: 7 | X8: 28 | Y8: 0 | AA8: =B8+G8+L8+Q8+V8 -> 262 | AB8: =(AA8+(B8/C8*D8+G8/H8*I8+L8/M8*N8+Q8/R8*S8+V8/W8*X8))/($D$1+$I$1+$N$1+$S$1+$X$1) -> 0.24944161 | AC8: =(E8+J8+O8+T8+Y8)/(AA8) -> 0.54198473
A9: Xin Zhao | B9: 134 | C9: 134 | D9: 73 | E9: 64 | G9: 7 | H9: 7 | I9: 1 | J9: 3 | L9: 94 | M9: 94 | N9: 50 | O9: 44 | Q9: 228 | R9: 228 | S9: 87 | T9: 124 | V9: 34 | W9: 34 | X9: 9 | Y9: 15 | AA9: =B9+G9+L9+Q9+V9 -> 497 | AB9: =(AA9+(B9/C9*D9+G9/H9*I9+L9/M9*N9+Q9/R9*S9+V9/W9*X9))/($D$1+$I$1+$N$1+$S$1+$X$1) -> 0.24454297 | AC9: =(E9+J9+O9+T9+Y9)/(AA9) -> 0.50301811
A10: Viego | B10: 205 | C10: 205 | D10: 88 | E10: 103 | G10: 116 | H10: 116 | I10: 97 | J10: 58 | L10: 88 | M10: 88 | N10: 49 | O10: 42 | Q10: 40 | R10: 42 | S10: 13 | T10: 17 | W10: 1 | AA10: =B10+G10+L10+Q10+V10 -> 449 | AB10: =(AA10+(B10/C10*D10+G10/H10*I10+L10/M10*N10+Q10/R10*S10+V10/W10*X10))/($D$1+$I$1+$N$1+$S$1+$X$1) -> 0.23716949 | AC10: =(E10+J10+O10+T10+Y10)/(AA10) -> 0.48997773
A11: Nocturne | B11: 23 | C11: 23 | D11: 20 | E11: 14 | G11: 34 | H11: 34 | I11: 48 | J11: 17 | L11: 45 | M11: 45 | N11: 56 | O11: 20 | Q11: 63 | R11: 63 | S11: 108 | T11: 33 | V11: 16 | W11: 16 | X11: 36 | Y11: 8 | AA11: =B11+G11+L11+Q11+V11 -> 181 | AB11: =(AA11+(B11/C11*D11+G11/H11*I11+L11/M11*N11+Q11/R11*S11+V11/W11*X11))/($D$1+$I$1+$N$1+$S$1+$X$1) -> 0.15313779 | AC11: =(E11+J11+O11+T11+Y11)/(AA11) -> 0.50828729
A12: Jarvan IV | B12: 57 | C12: 60 | D12: 60 | E12: 23 | G12: 42 | H12: 45 | I12: 51 | J12: 21 | L12: 24 | M12: 24 | N12: 24 | O12: 11 | Q12: 85 | R12: 85 | S12: 28 | T12: 49 | V12: 33 | W12: 33 | X12: 21 | Y12: 17 | AA12: =B12+G12+L12+Q12+V12 -> 241 | AB12: =(AA12+(B12/C12*D12+G12/H12*I12+L12/M12*N12+Q12/R12*S12+V12/W12*X12))/($D$1+$I$1+$N$1+$S$1+$X$1) -> 0.14276944 | AC12: =(E12+J12+O12+T12+Y12)/(AA12) -> 0.50207469
A13: Skarner | B13: 14 | C13: 14 | D13: 14 | E13: 8 | G13: 7 | H13: 7 | I13: 7 | J13: 4 | L13: 50 | M13: 97 | N13: 82 | O13: 34 | Q13: 96 | R13: 96 | S13: 155 | T13: 42 | W13: 1 | AA13: =B13+G13+L13+Q13+V13 -> 167 | AB13: =(AA13+(B13/C13*D13+G13/H13*I13+L13/M13*N13+Q13/R13*S13+V13/W13*X13))/($D$1+$I$1+$N$1+$S$1+$X$1) -> 0.13140111 | AC13: =(E13+J13+O13+T13+Y13)/(AA13) -> 0.52694611
A14: Trundle | B14: 86 | C14: 87 | D14: 79 | E14: 40 | H14: 1 | L14: 3 | M14: 3 | N14: 2 | O14: 1 | Q14: 100 | R14: 100 | S14: 88 | T14: 45 | V14: 7 | W14: 7 | X14: 6 | Y14: 6 | AA14: =B14+G14+L14+Q14+V14 -> 196 | AB14: =(AA14+(B14/C14*D14+G14/H14*I14+L14/M14*N14+Q14/R14*S14+V14/W14*X14))/($D$1+$I$1+$N$1+$S$1+$X$1) -> 0.12622509 | AC14: =(E14+J14+O14+T14+Y14)/(AA14) -> 0.46938776
A15: Pantheon | B15: 2 | C15: 3 | D15: 6 | E15: 0 | H15: 1 | M15: 1 | Q15: 108 | R15: 122 | S15: 226 | T15: 56 | V15: 27 | W15: 30 | X15: 30 | Y15: 16 | AA15: =B15+G15+L15+Q15+V15 -> 137 | AB15: =(AA15+(B15/C15*D15+G15/H15*I15+L15/M15*N15+Q15/R15*S15+V15/W15*X15))/($D$1+$I$1+$N$1+$S$1+$X$1) -> 0.12553396 | AC15: =(E15+J15+O15+T15+Y15)/(AA15) -> 0.52554745
A16: Nidalee | B16: 11 | C16: 11 | D16: 5 | E16: 4 | G16: 15 | H16: 15 | I16: 27 | J16: 7 | L16: 61 | M16: 61 | N16: 93 | O16: 37 | Q16: 45 | R16: 55 | S16: 63 | T16: 31 | V16: 1 | W16: 1 | X16: 0 | Y16: 1 | AA16: =B16+G16+L16+Q16+V16 -> 133 | AB16: =(AA16+(B16/C16*D16+G16/H16*I16+L16/M16*N16+Q16/R16*S16+V16/W16*X16))/($D$1+$I$1+$N$1+$S$1+$X$1) -> 0.10557485 | AC16: =(E16+J16+O16+T16+Y16)/(AA16) -> 0.60150376
A17: Elise | C17: 1 | G17: 35 | H17: 35 | I17: 153 | J17: 21 | L17: 1 | M17: 1 | N17: 0 | O17: 0 | R17: 1 | W17: 1 | AA17: =B17+G17+L17+Q17+V17 -> 36 | AB17: =(AA17+(B17/C17*D17+G17/H17*I17+L17/M17*N17+Q17/R17*S17+V17/W17*X17))/($D$1+$I$1+$N$1+$S$1+$X$1) -> 0.064461119 | AC17: =(E17+J17+O17+T17+Y17)/(AA17) -> 0.58333333
A18: Ivern | C18: 1 | G18: 18 | H18: 18 | I18: 33 | J18: 8 | L18: 34 | M18: 34 | N18: 67 | O18: 17 | Q18: 11 | R18: 11 | S18: 6 | T18: 6 | W18: 1 | AA18: =B18+G18+L18+Q18+V18 -> 63 | AB18: =(AA18+(B18/C18*D18+G18/H18*I18+L18/M18*N18+Q18/R18*S18+V18/W18*X18))/($D$1+$I$1+$N$1+$S$1+$X$1) -> 0.057639836 | AC18: =(E18+J18+O18+T18+Y18)/(AA18) -> 0.49206349
A19: Lillia | B19: 4 | C19: 7 | D19: 2 | E19: 1 | G19: 6 | H19: 6 | I19: 2 | J19: 4 | L19: 38 | M19: 38 | N19: 29 | O19: 17 | Q19: 33 | R19: 33 | S19: 37 | T19: 17 | V19: 1 | W19: 1 | X19: 0 | Y19: 1 | AA19: =B19+G19+L19+Q19+V19 -> 82 | AB19: =(AA19+(B19/C19*D19+G19/H19*I19+L19/M19*N19+Q19/R19*S19+V19/W19*X19))/($D$1+$I$1+$N$1+$S$1+$X$1) -> 0.051549406 | AC19: =(E19+J19+O19+T19+Y19)/(AA19) -> 0.48780488
A20: Hecarim | B20: 59 | C20: 59 | D20: 79 | E20: 32 | H20: 1 | M20: 1 | Q20: 1 | R20: 1 | S20: 0 | T20: 1 | V20: 1 | W20: 1 | X20: 0 | Y20: 0 | AA20: =B20+G20+L20+Q20+V20 -> 61 | AB20: =(AA20+(B20/C20*D20+G20/H20*I20+L20/M20*N20+Q20/R20*S20+V20/W20*X20))/($D$1+$I$1+$N$1+$S$1+$X$1) -> 0.047748977 | AC20: =(E20+J20+O20+T20+Y20)/(AA20) -> 0.54098361
A21: Rell | C21: 1 | G21: 39 | H21: 150 | I21: 83 | J21: 24 | L21: 53 | M21: 222 | N21: 110 | O21: 29 | R21: 1 | W21: 1 | AA21: =B21+G21+L21+Q21+V21 -> 92 | AB21: =(AA21+(B21/C21*D21+G21/H21*I21+L21/M21*N21+Q21/R21*S21+V21/W21*X21))/($D$1+$I$1+$N$1+$S$1+$X$1) -> 0.047694837 | AC21: =(E21+J21+O21+T21+Y21)/(AA21) -> 0.57608696
A22: Zyra | C22: 1 | H22: 1 | L22: 42 | M22: 43 | N22: 32 | O22: 16 | Q22: 18 | R22: 18 | S22: 46 | T22: 5 | W22: 1 | AA22: =B22+G22+L22+Q22+V22 -> 60 | AB22: =(AA22+(B22/C22*D22+G22/H22*I22+L22/M22*N22+Q22/R22*S22+V22/W22*X22))/($D$1+$I$1+$N$1+$S$1+$X$1) -> 0.046813033 | AC22: =(E22+J22+O22+T22+Y22)/(AA22) -> 0.35
A23: Graves | B23: 63 | C23: 111 | D23: 114 | E23: 32 | G23: 2 | H23: 3 | I23: 0 | J23: 1 | L23: 5 | M23: 5 | N23: 0 | O23: 0 | R23: 1 | W23: 1 | AA23: =B23+G23+L23+Q23+V23 -> 70 | AB23: =(AA23+(B23/C23*D23+G23/H23*I23+L23/M23*N23+Q23/R23*S23+V23/W23*X23))/($D$1+$I$1+$N$1+$S$1+$X$1) -> 0.045942259 | AC23: =(E23+J23+O23+T23+Y23)/(AA23) -> 0.47142857
A24: Naafiri | C24: 1 | H24: 1 | M24: 1 | Q24: 72 | R24: 72 | S24: 53 | T24: 30 | V24: 3 | W24: 3 | X24: 1 | Y24: 1 | AA24: =B24+G24+L24+Q24+V24 -> 75 | AB24: =(AA24+(B24/C24*D24+G24/H24*I24+L24/M24*N24+Q24/R24*S24+V24/W24*X24))/($D$1+$I$1+$N$1+$S$1+$X$1) -> 0.043997271 | AC24: =(E24+J24+O24+T24+Y24)/(AA24) -> 0.41333333
A25: Diana | B25: 24 | C25: 24 | D25: 51 | E25: 14 | G25: 1 | H25: 1 | I25: 0 | J25: 0 | L25: 2 | M25: 3 | N25: 2 | O25: 1 | Q25: 1 | R25: 2 | S25: 1 | T25: 0 | W25: 1 | AA25: =B25+G25+L25+Q25+V25 -> 28 | AB25: =(AA25+(B25/C25*D25+G25/H25*I25+L25/M25*N25+Q25/R25*S25+V25/W25*X25))/($D$1+$I$1+$N$1+$S$1+$X$1) -> 0.02756935 | AC25: =(E25+J25+O25+T25+Y25)/(AA25) -> 0.53571429
A26: Volibear | B26: 35 | C26: 36 | D26: 22 | E26: 15 | G26: 6 | H26: 8 | I26: 8 | J26: 4 | L26: 5 | M26: 7 | N26: 8 | O26: 1 | R26: 1 | W26: 1 | AA26: =B26+G26+L26+Q26+V26 -> 46 | AB26: =(AA26+(B26/C26*D26+G26/H26*I26+L26/M26*N26+Q26/R26*S26+V26/W26*X26))/($D$1+$I$1+$N$1+$S$1+$X$1) -> 0.026979255 | AC26: =(E26+J26+O26+T26+Y26)/(AA26) -> 0.43478261
A27: Kindred | B27: 8 | C27: 8 | D27: 8 | E27: 8 | G27: 17 | H27: 17 | I27: 19 | J27: 6 | L27: 6 | M27: 6 | N27: 7 | O27: 4 | Q27: 8 | R27: 8 | S27: 3 | T27: 2 | W27: 1 | AA27: =B27+G27+L27+Q27+V27 -> 39 | AB27: =(AA27+(B27/C27*D27+G27/H27*I27+L27/M27*N27+Q27/R27*S27+V27/W27*X27))/($D$1+$I$1+$N$1+$S$1+$X$1) -> 0.025920873 | AC27: =(E27+J27+O27+T27+Y27)/(AA27) -> 0.51282051
A28: Malphite | C28: 1 | H28: 1 | M28: 1 | R28: 1 | V28: 6 | W28: 6 | X28: 64 | Y28: 1 | AA28: =B28+G28+L28+Q28+V28 -> 6 | AB28: =(AA28+(B28/C28*D28+G28/H28*I28+L28/M28*N28+Q28/R28*S28+V28/W28*X28))/($D$1+$I$1+$N$1+$S$1+$X$1) -> 0.023874488 | AC28: =(E28+J28+O28+T28+Y28)/(AA28) -> 0.16666667
A29: Kha'Zix | C29: 1 | G29: 43 | H29: 43 | I29: 13 | J29: 28 | L29: 5 | M29: 5 | N29: 1 | O29: 3 | Q29: 1 | R29: 1 | S29: 0 | T29: 0 | V29: 1 | W29: 1 | X29: 1 | Y29: 0 | AA29: =B29+G29+L29+Q29+V29 -> 50 | AB29: =(AA29+(B29/C29*D29+G29/H29*I29+L29/M29*N29+Q29/R29*S29+V29/W29*X29))/($D$1+$I$1+$N$1+$S$1+$X$1) -> 0.022169168 | AC29: =(E29+J29+O29+T29+Y29)/(AA29) -> 0.62
A30: Qiyana | B30: 1 | C30: 1 | D30: 0 | E30: 0 | H30: 1 | M30: 1 | Q30: 21 | R30: 21 | S30: 31 | T30: 7 | V30: 3 | W30: 3 | X30: 5 | Y30: 0 | AA30: =B30+G30+L30+Q30+V30 -> 25 | AB30: =(AA30+(B30/C30*D30+G30/H30*I30+L30/M30*N30+Q30/R30*S30+V30/W30*X30))/($D$1+$I$1+$N$1+$S$1+$X$1) -> 0.020804911 | AC30: =(E30+J30+O30+T30+Y30)/(AA30) -> 0.28
A31: Brand | C31: 1 | H31: 1 | L31: 23 | M31: 23 | N31: 21 | O31: 9 | Q31: 2 | R31: 2 | S31: 1 | T31: 0 | W31: 1 | AA31: =B31+G31+L31+Q31+V31 -> 25 | AB31: =(AA31+(B31/C31*D31+G31/H31*I31+L31/M31*N31+Q31/R31*S31+V31/W31*X31))/($D$1+$I$1+$N$1+$S$1+$X$1) -> 0.016030014 | AC31: =(E31+J31+O31+T31+Y31)/(AA31) -> 0.36
A32: Taliyah | B32: 4 | C32: 56 | D32: 97 | E32: 3 | G32: 6 | H32: 84 | I32: 54 | J32: 1 | L32: 12 | M32: 155 | N32: 140 | O32: 5 | R32: 1 | W32: 1 | AA32: =B32+G32+L32+Q32+V32 -> 22 | AB32: =(AA32+(B32/C32*D32+G32/H32*I32+L32/M32*N32+Q32/R32*S32+V32/W32*X32))/($D$1+$I$1+$N$1+$S$1+$X$1) -> 0.014878726 | AC32: =(E32+J32+O32+T32+Y32)/(AA32) -> 0.40909091
A33: Jax | C33: 1 | G33: 1 | H33: 189 | I33: 185 | J33: 0 | L33: 18 | M33: 121 | N33: 105 | O33: 11 | Q33: 2 | R33: 78 | S33: 55 | T33: 2 | V33: 2 | W33: 11 | X33: 8 | Y33: 2 | AA33: =B33+G33+L33+Q33+V33 -> 23 | AB33: =(AA33+(B33/C33*D33+G33/H33*I33+L33/M33*N33+Q33/R33*S33+V33/W33*X33))/($D$1+$I$1+$N$1+$S$1+$X$1) -> 0.014482767 | AC33: =(E33+J33+O33+T33+Y33)/(AA33) -> 0.65217391
A34: Bel'Veth | B34: 13 | C34: 13 | D34: 9 | E34: 4 | G34: 8 | H34: 8 | I34: 5 | J34: 3 | L34: 2 | M34: 2 | N34: 2 | O34: 0 | R34: 1 | W34: 1 | AA34: =B34+G34+L34+Q34+V34 -> 23 | AB34: =(AA34+(B34/C34*D34+G34/H34*I34+L34/M34*N34+Q34/R34*S34+V34/W34*X34))/($D$1+$I$1+$N$1+$S$1+$X$1) -> 0.013301501 | AC34: =(E34+J34+O34+T34+Y34)/(AA34) -> 0.30434783
A35: Jayce | C35: 1 | H35: 1 | M35: 1 | R35: 1 | V35: 5 | W35: 11 | X35: 74 | Y35: 1 | AA35: =B35+G35+L35+Q35+V35 -> 5 | AB35: =(AA35+(B35/C35*D35+G35/H35*I35+L35/M35*N35+Q35/R35*S35+V35/W35*X35))/($D$1+$I$1+$N$1+$S$1+$X$1) -> 0.013177477 | AC35: =(E35+J35+O35+T35+Y35)/(AA35) -> 0.2
A36: Zed | C36: 1 | H36: 1 | M36: 1 | Q36: 14 | R36: 15 | S36: 13 | T36: 8 | W36: 1 | AA36: =B36+G36+L36+Q36+V36 -> 14 | AB36: =(AA36+(B36/C36*D36+G36/H36*I36+L36/M36*N36+Q36/R36*S36+V36/W36*X36))/($D$1+$I$1+$N$1+$S$1+$X$1) -> 0.0089131423 | AC36: =(E36+J36+O36+T36+Y36)/(AA36) -> 0.57142857
A37: Dr. Mundo | C37: 1 | H37: 1 | M37: 1 | Q37: 6 | R37: 6 | S37: 2 | T37: 5 | V37: 10 | W37: 10 | X37: 7 | Y37: 6 | AA37: =B37+G37+L37+Q37+V37 -> 16 | AB37: =(AA37+(B37/C37*D37+G37/H37*I37+L37/M37*N37+Q37/R37*S37+V37/W37*X37))/($D$1+$I$1+$N$1+$S$1+$X$1) -> 0.008526603 | AC37: =(E37+J37+O37+T37+Y37)/(AA37) -> 0.6875
A38: Rek'Sai | B38: 8 | C38: 8 | D38: 3 | E38: 3 | G38: 1 | H38: 1 | I38: 0 | J38: 0 | L38: 6 | M38: 21 | N38: 23 | O38: 3 | R38: 1 | W38: 1 | AA38: =B38+G38+L38+Q38+V38 -> 15 | AB38: =(AA38+(B38/C38*D38+G38/H38*I38+L38/M38*N38+Q38/R38*S38+V38/W38*X38))/($D$1+$I$1+$N$1+$S$1+$X$1) -> 0.0083804327 | AC38: =(E38+J38+O38+T38+Y38)/(AA38) -> 0.4
A39: Ambessa | C39: 1 | H39: 1 | M39: 1 | R39: 1 | V39: 11 | W39: 31 | X39: 33 | Y39: 7 | AA39: =B39+G39+L39+Q39+V39 -> 11 | AB39: =(AA39+(B39/C39*D39+G39/H39*I39+L39/M39*N39+Q39/R39*S39+V39/W39*X39))/($D$1+$I$1+$N$1+$S$1+$X$1) -> 0.0077454561 | AC39: =(E39+J39+O39+T39+Y39)/(AA39) -> 0.63636364
A40: Neeko | C40: 1 | G40: 4 | H40: 54 | I40: 244 | J40: 3 | M40: 1 | R40: 1 | W40: 1 | AA40: =B40+G40+L40+Q40+V40 -> 4 | AB40: =(AA40+(B40/C40*D40+G40/H40*I40+L40/M40*N40+Q40/R40*S40+V40/W40*X40))/($D$1+$I$1+$N$1+$S$1+$X$1) -> 0.0075286747 | AC40: =(E40+J40+O40+T40+Y40)/(AA40) -> 0.75
...

Sheet Mid
A1: Mid | B1: 2022 | C1: Games: | D1: 686 | G1: 2023 | H1: Games: | I1: 688 | L1: 2024 | M1: Games: | N1: 679 | Q1: 2025 | R1: Games: | S1: 754 | V1: 2026 | W1: Games: | X1: 125
A2: Champion | B2: Picks | C2: Total | D2: Bans | E2: Wins | G2: Picks | H2: Total | I2: Bans | J2: Wins | L2: Picks | M2: Total | N2: Bans | O2: Wins | Q2: Picks | R2: Total | S2: Bans | T2: Wins | V2: Picks | W2: Total | X2: Bans | Y2: Wins | AA2: Total Picks | AB2: Pickrate | AC2: Winrate
A3: Azir | B3: 157 | C3: 159 | D3: 144 | E3: 79 | G3: 234 | H3: 235 | I3: 137 | J3: 124 | L3: 187 | M3: 187 | N3: 119 | O3: 92 | Q3: 154 | R3: 154 | S3: 354 | T3: 81 | V3: 31 | W3: 31 | X3: 32 | Y3: 13 | AA3: =B3+G3+L3+Q3+V3 -> 763 | AB3: =(AA3+(B3/C3*D3+G3/H3*I3+L3/M3*N3+Q3/R3*S3+V3/W3*X3))/($D$1+$I$1+$N$1+$S$1+$X$1) -> 0.52749171 | AC3: =(E3+J3+O3+T3+Y3)/(AA3) -> 0.50982962
A4: Taliyah | B4: 52 | C4: 56 | D4: 97 | E4: 22 | G4: 78 | H4: 84 | I4: 54 | J4: 35 | L4: 142 | M4: 155 | N4: 140 | O4: 76 | Q4: 178 | R4: 178 | S4: 225 | T4: 105 | V4: 33 | W4: 33 | X4: 3 | Y4: 13 | AA4: =B4+G4+L4+Q4+V4 -> 483 | AB4: =(AA4+(B4/C4*D4+G4/H4*I4+L4/M4*N4+Q4/R4*S4+V4/W4*X4))/($D$1+$I$1+$N$1+$S$1+$X$1) -> 0.33406288 | AC4: =(E4+J4+O4+T4+Y4)/(AA4) -> 0.51966874
A5: Ahri | B5: 177 | C5: 177 | D5: 163 | E5: 90 | G5: 116 | H5: 117 | I5: 91 | J5: 49 | L5: 76 | M5: 76 | N5: 71 | O5: 41 | Q5: 133 | R5: 133 | S5: 44 | T5: 59 | V5: 16 | W5: 16 | X5: 11 | Y5: 10 | AA5: =B5+G5+L5+Q5+V5 -> 518 | AB5: =(AA5+(B5/C5*D5+G5/H5*I5+L5/M5*N5+Q5/R5*S5+V5/W5*X5))/($D$1+$I$1+$N$1+$S$1+$X$1) -> 0.30601031 | AC5: =(E5+J5+O5+T5+Y5)/(AA5) -> 0.48069498
A6: Orianna | B6: 28 | C6: 28 | D6: 12 | E6: 12 | G6: 47 | H6: 47 | I6: 63 | J6: 27 | L6: 100 | M6: 100 | N6: 180 | O6: 51 | Q6: 102 | R6: 102 | S6: 107 | T6: 55 | V6: 27 | W6: 27 | X6: 48 | Y6: 13 | AA6: =B6+G6+L6+Q6+V6 -> 304 | AB6: =(AA6+(B6/C6*D6+G6/H6*I6+L6/M6*N6+Q6/R6*S6+V6/W6*X6))/($D$1+$I$1+$N$1+$S$1+$X$1) -> 0.24351978 | AC6: =(E6+J6+O6+T6+Y6)/(AA6) -> 0.51973684
A7: LeBlanc | B7: 102 | C7: 102 | D7: 168 | E7: 49 | G7: 68 | H7: 70 | I7: 200 | J7: 29 | L7: 38 | M7: 38 | N7: 93 | O7: 20 | Q7: 11 | R7: 12 | S7: 20 | T7: 8 | V7: 2 | W7: 2 | X7: 9 | Y7: 1 | AA7: =B7+G7+L7+Q7+V7 -> 221 | AB7: =(AA7+(B7/C7*D7+G7/H7*I7+L7/M7*N7+Q7/R7*S7+V7/W7*X7))/($D$1+$I$1+$N$1+$S$1+$X$1) -> 0.23997921 | AC7: =(E7+J7+O7+T7+Y7)/(AA7) -> 0.4841629
A8: Yone | B8: 12 | C8: 22 | D8: 16 | E8: 7 | G8: 45 | H8: 50 | I8: 59 | J8: 29 | L8: 109 | M8: 121 | N8: 132 | O8: 64 | Q8: 88 | R8: 88 | S8: 223 | T8: 46 | V8: 8 | W8: 8 | X8: 9 | Y8: 3 | AA8: =B8+G8+L8+Q8+V8 -> 262 | AB8: =(AA8+(B8/C8*D8+G8/H8*I8+L8/M8*N8+Q8/R8*S8+V8/W8*X8))/($D$1+$I$1+$N$1+$S$1+$X$1) -> 0.23012836 | AC8: =(E8+J8+O8+T8+Y8)/(AA8) -> 0.56870229
A9: Corki | B9: 68 | C9: 68 | D9: 171 | E9: 38 | G9: 8 | H9: 8 | I9: 1 | J9: 5 | L9: 193 | M9: 202 | N9: 127 | O9: 94 | Q9: 46 | R9: 161 | S9: 64 | T9: 16 | W9: 1 | AA9: =B9+G9+L9+Q9+V9 -> 315 | AB9: =(AA9+(B9/C9*D9+G9/H9*I9+L9/M9*N9+Q9/R9*S9+V9/W9*X9))/($D$1+$I$1+$N$1+$S$1+$X$1) -> 0.21372009 | AC9: =(E9+J9+O9+T9+Y9)/(AA9) -> 0.48571429
A10: Sylas | B10: 124 | C10: 128 | D10: 164 | E10: 81 | G10: 78 | H10: 80 | I10: 88 | J10: 45 | L10: 25 | M10: 26 | N10: 16 | O10: 16 | Q10: 60 | R10: 69 | S10: 49 | T10: 30 | V10: 5 | W10: 8 | X10: 9 | Y10: 4 | AA10: =B10+G10+L10+Q10+V10 -> 292 | AB10: =(AA10+(B10/C10*D10+G10/H10*I10+L10/M10*N10+Q10/R10*S10+V10/W10*X10))/($D$1+$I$1+$N$1+$S$1+$X$1) -> 0.20473851 | AC10: =(E10+J10+O10+T10+Y10)/(AA10) -> 0.60273973
A11: Ryze | B11: 91 | C11: 93 | D11: 133 | E11: 44 | G11: 16 | H11: 20 | I11: 59 | J11: 6 | L11: 2 | M11: 4 | N11: 0 | O11: 0 | Q11: 142 | R11: 143 | S11: 52 | T11: 76 | V11: 35 | W11: 36 | X11: 13 | Y11: 23 | AA11: =B11+G11+L11+Q11+V11 -> 286 | AB11: =(AA11+(B11/C11*D11+G11/H11*I11+L11/M11*N11+Q11/R11*S11+V11/W11*X11))/($D$1+$I$1+$N$1+$S$1+$X$1) -> 0.17995056 | AC11: =(E11+J11+O11+T11+Y11)/(AA11) -> 0.52097902
A12: Tristana | B12: 1 | C12: 37 | D12: 25 | E12: 1 | G12: 72 | H12: 85 | I12: 139 | J12: 40 | L12: 135 | M12: 140 | N12: 154 | O12: 64 | Q12: 15 | R12: 24 | S12: 12 | T12: 7 | V12: 2 | W12: 3 | X12: 0 | Y12: 1 | AA12: =B12+G12+L12+Q12+V12 -> 225 | AB12: =(AA12+(B12/C12*D12+G12/H12*I12+L12/M12*N12+Q12/R12*S12+V12/W12*X12))/($D$1+$I$1+$N$1+$S$1+$X$1) -> 0.17033317 | AC12: =(E12+J12+O12+T12+Y12)/(AA12) -> 0.50222222
A13: Annie | C13: 1 | G13: 96 | H13: 107 | I13: 247 | J13: 60 | L13: 8 | M13: 10 | N13: 1 | O13: 3 | Q13: 80 | R13: 80 | S13: 62 | T13: 44 | V13: 1 | W13: 1 | X13: 0 | Y13: 1 | AA13: =B13+G13+L13+Q13+V13 -> 185 | AB13: =(AA13+(B13/C13*D13+G13/H13*I13+L13/M13*N13+Q13/R13*S13+V13/W13*X13))/($D$1+$I$1+$N$1+$S$1+$X$1) -> 0.16009805 | AC13: =(E13+J13+O13+T13+Y13)/(AA13) -> 0.58378378
A14: Akali | B14: 69 | C14: 108 | D14: 141 | E14: 37 | G14: 66 | H14: 68 | I14: 85 | J14: 27 | L14: 36 | M14: 37 | N14: 25 | O14: 15 | Q14: 33 | R14: 35 | S14: 36 | T14: 13 | V14: 10 | W14: 11 | X14: 21 | Y14: 3 | AA14: =B14+G14+L14+Q14+V14 -> 214 | AB14: =(AA14+(B14/C14*D14+G14/H14*I14+L14/M14*N14+Q14/R14*S14+V14/W14*X14))/($D$1+$I$1+$N$1+$S$1+$X$1) -> 0.15823377 | AC14: =(E14+J14+O14+T14+Y14)/(AA14) -> 0.44392523
A15: Twisted Fate | B15: 51 | C15: 51 | D15: 249 | E15: 28 | G15: 12 | H15: 12 | I15: 2 | J15: 8 | L15: 4 | M15: 54 | N15: 107 | O15: 2 | Q15: 22 | R15: 22 | S15: 57 | T15: 7 | V15: 6 | W15: 6 | X15: 6 | Y15: 4 | AA15: =B15+G15+L15+Q15+V15 -> 95 | AB15: =(AA15+(B15/C15*D15+G15/H15*I15+L15/M15*N15+Q15/R15*S15+V15/W15*X15))/($D$1+$I$1+$N$1+$S$1+$X$1) -> 0.14219847 | AC15: =(E15+J15+O15+T15+Y15)/(AA15) -> 0.51578947
A16: Viktor | B16: 106 | C16: 108 | D16: 49 | E16: 42 | G16: 35 | H16: 35 | I16: 15 | J16: 12 | M16: 1 | Q16: 101 | R16: 102 | S16: 65 | T16: 44 | V16: 6 | W16: 6 | X16: 3 | Y16: 2 | AA16: =B16+G16+L16+Q16+V16 -> 248 | AB16: =(AA16+(B16/C16*D16+G16/H16*I16+L16/M16*N16+Q16/R16*S16+V16/W16*X16))/($D$1+$I$1+$N$1+$S$1+$X$1) -> 0.12907754 | AC16: =(E16+J16+O16+T16+Y16)/(AA16) -> 0.40322581
A17: Neeko | C17: 1 | G17: 49 | H17: 54 | I17: 244 | J17: 33 | L17: 16 | M17: 40 | N17: 35 | O17: 10 | Q17: 1 | R17: 121 | S17: 166 | T17: 0 | W17: 1 | AA17: =B17+G17+L17+Q17+V17 -> 66 | AB17: =(AA17+(B17/C17*D17+G17/H17*I17+L17/M17*N17+Q17/R17*S17+V17/W17*X17))/($D$1+$I$1+$N$1+$S$1+$X$1) -> 0.10326716 | AC17: =(E17+J17+O17+T17+Y17)/(AA17) -> 0.65151515
A18: Galio | B18: 61 | C18: 63 | D18: 35 | E18: 27 | G18: 6 | H18: 8 | I18: 4 | J18: 1 | L18: 6 | M18: 12 | N18: 3 | O18: 5 | Q18: 92 | R18: 113 | S18: 70 | T18: 46 | V18: 12 | W18: 12 | X18: 5 | Y18: 8 | AA18: =B18+G18+L18+Q18+V18 -> 177 | AB18: =(AA18+(B18/C18*D18+G18/H18*I18+L18/M18*N18+Q18/R18*S18+V18/W18*X18))/($D$1+$I$1+$N$1+$S$1+$X$1) -> 0.094604379 | AC18: =(E18+J18+O18+T18+Y18)/(AA18) -> 0.49152542
A19: Aurora | C19: 1 | H19: 1 | L19: 14 | M19: 32 | N19: 95 | O19: 8 | Q19: 97 | R19: 147 | S19: 133 | T19: 43 | V19: 15 | W19: 24 | X19: 16 | Y19: 7 | AA19: =B19+G19+L19+Q19+V19 -> 126 | AB19: =(AA19+(B19/C19*D19+G19/H19*I19+L19/M19*N19+Q19/R19*S19+V19/W19*X19))/($D$1+$I$1+$N$1+$S$1+$X$1) -> 0.090492635 | AC19: =(E19+J19+O19+T19+Y19)/(AA19) -> 0.46031746
A20: Jayce | B20: 2 | C20: 66 | D20: 91 | E20: 1 | G20: 86 | H20: 143 | I20: 154 | J20: 39 | L20: 11 | M20: 29 | N20: 38 | O20: 7 | Q20: 11 | R20: 126 | S20: 118 | T20: 8 | V20: 1 | W20: 11 | X20: 74 | Y20: 1 | AA20: =B20+G20+L20+Q20+V20 -> 111 | AB20: =(AA20+(B20/C20*D20+G20/H20*I20+L20/M20*N20+Q20/R20*S20+V20/W20*X20))/($D$1+$I$1+$N$1+$S$1+$X$1) -> 0.081110373 | AC20: =(E20+J20+O20+T20+Y20)/(AA20) -> 0.5045045
A21: Syndra | B21: 30 | C21: 32 | D21: 27 | E21: 13 | G21: 50 | H21: 50 | I21: 35 | J21: 17 | L21: 21 | M21: 21 | N21: 12 | O21: 11 | Q21: 10 | R21: 10 | S21: 4 | T21: 6 | V21: 11 | W21: 11 | X21: 2 | Y21: 5 | AA21: =B21+G21+L21+Q21+V21 -> 122 | AB21: =(AA21+(B21/C21*D21+G21/H21*I21+L21/M21*N21+Q21/R21*S21+V21/W21*X21))/($D$1+$I$1+$N$1+$S$1+$X$1) -> 0.068319407 | AC21: =(E21+J21+O21+T21+Y21)/(AA21) -> 0.42622951
A22: Lissandra | B22: 55 | C22: 55 | D22: 56 | E22: 29 | G22: 34 | H22: 36 | I22: 28 | J22: 15 | L22: 1 | M22: 1 | N22: 0 | O22: 0 | Q22: 1 | R22: 1 | S22: 2 | T22: 1 | W22: 1 | AA22: =B22+G22+L22+Q22+V22 -> 91 | AB22: =(AA22+(B22/C22*D22+G22/H22*I22+L22/M22*N22+Q22/R22*S22+V22/W22*X22))/($D$1+$I$1+$N$1+$S$1+$X$1) -> 0.059837805 | AC22: =(E22+J22+O22+T22+Y22)/(AA22) -> 0.49450549
A23: Kassadin | B23: 2 | C23: 2 | D23: 1 | E23: 0 | G23: 22 | H23: 22 | I23: 97 | J23: 14 | L23: 3 | M23: 3 | N23: 2 | O23: 3 | Q23: 3 | R23: 3 | S23: 0 | T23: 1 | W23: 1 | AA23: =B23+G23+L23+Q23+V23 -> 30 | AB23: =(AA23+(B23/C23*D23+G23/H23*I23+L23/M23*N23+Q23/R23*S23+V23/W23*X23))/($D$1+$I$1+$N$1+$S$1+$X$1) -> 0.044338336 | AC23: =(E23+J23+O23+T23+Y23)/(AA23) -> 0.6
A24: Hwei | C24: 1 | H24: 1 | L24: 47 | M24: 54 | N24: 42 | O24: 19 | Q24: 23 | R24: 23 | S24: 11 | T24: 6 | W24: 1 | AA24: =B24+G24+L24+Q24+V24 -> 70 | AB24: =(AA24+(B24/C24*D24+G24/H24*I24+L24/M24*N24+Q24/R24*S24+V24/W24*X24))/($D$1+$I$1+$N$1+$S$1+$X$1) -> 0.040093982 | AC24: =(E24+J24+O24+T24+Y24)/(AA24) -> 0.35714286
A25: Cassiopeia | B25: 1 | C25: 1 | D25: 0 | E25: 0 | G25: 14 | H25: 16 | I25: 11 | J25: 4 | L25: 3 | M25: 3 | N25: 3 | O25: 1 | Q25: 29 | R25: 29 | S25: 29 | T25: 13 | V25: 8 | W25: 8 | X25: 10 | Y25: 4 | AA25: =B25+G25+L25+Q25+V25 -> 55 | AB25: =(AA25+(B25/C25*D25+G25/H25*I25+L25/M25*N25+Q25/R25*S25+V25/W25*X25))/($D$1+$I$1+$N$1+$S$1+$X$1) -> 0.036365962 | AC25: =(E25+J25+O25+T25+Y25)/(AA25) -> 0.4
A26: Vex | B26: 51 | C26: 51 | D26: 39 | E26: 23 | G26: 2 | H26: 2 | I26: 0 | J26: 2 | L26: 3 | M26: 3 | N26: 0 | O26: 1 | Q26: 2 | R26: 2 | S26: 1 | T26: 1 | W26: 1 | AA26: =B26+G26+L26+Q26+V26 -> 58 | AB26: =(AA26+(B26/C26*D26+G26/H26*I26+L26/M26*N26+Q26/R26*S26+V26/W26*X26))/($D$1+$I$1+$N$1+$S$1+$X$1) -> 0.033424284 | AC26: =(E26+J26+O26+T26+Y26)/(AA26) -> 0.46551724
A27: Zoe | B27: 32 | C27: 32 | D27: 23 | E27: 15 | G27: 1 | H27: 1 | I27: 1 | J27: 0 | M27: 1 | Q27: 7 | R27: 7 | S27: 4 | T27: 5 | V27: 9 | W27: 9 | X27: 8 | Y27: 6 | AA27: =B27+G27+L27+Q27+V27 -> 49 | AB27: =(AA27+(B27/C27*D27+G27/H27*I27+L27/M27*N27+Q27/R27*S27+V27/W27*X27))/($D$1+$I$1+$N$1+$S$1+$X$1) -> 0.02899045 | AC27: =(E27+J27+O27+T27+Y27)/(AA27) -> 0.53061224
A28: Veigar | B28: 13 | C28: 13 | D28: 8 | E28: 6 | G28: 31 | H28: 31 | I28: 19 | J28: 15 | L28: 5 | M28: 6 | N28: 2 | O28: 2 | Q28: 2 | R28: 2 | S28: 0 | T28: 2 | W28: 1 | AA28: =B28+G28+L28+Q28+V28 -> 51 | AB28: =(AA28+(B28/C28*D28+G28/H28*I28+L28/M28*N28+Q28/R28*S28+V28/W28*X28))/($D$1+$I$1+$N$1+$S$1+$X$1) -> 0.027171442 | AC28: =(E28+J28+O28+T28+Y28)/(AA28) -> 0.49019608
A29: Aurelion Sol | C29: 1 | G29: 8 | H29: 8 | I29: 9 | J29: 2 | L29: 32 | M29: 32 | N29: 24 | O29: 14 | Q29: 3 | R29: 3 | S29: 0 | T29: 0 | W29: 1 | AA29: =B29+G29+L29+Q29+V29 -> 43 | AB29: =(AA29+(B29/C29*D29+G29/H29*I29+L29/M29*N29+Q29/R29*S29+V29/W29*X29))/($D$1+$I$1+$N$1+$S$1+$X$1) -> 0.025920873 | AC29: =(E29+J29+O29+T29+Y29)/(AA29) -> 0.37209302
A30: Lucian | B30: 2 | C30: 79 | D30: 260 | E30: 1 | H30: 1 | L30: 27 | M30: 126 | N30: 177 | O30: 12 | R30: 1 | W30: 1 | AA30: =B30+G30+L30+Q30+V30 -> 29 | AB30: =(AA30+(B30/C30*D30+G30/H30*I30+L30/M30*N30+Q30/R30*S30+V30/W30*X30))/($D$1+$I$1+$N$1+$S$1+$X$1) -> 0.025071913 | AC30: =(E30+J30+O30+T30+Y30)/(AA30) -> 0.44827586
A31: Smolder | C31: 1 | H31: 1 | L31: 29 | M31: 73 | N31: 75 | O31: 14 | Q31: 8 | R31: 19 | S31: 10 | T31: 5 | V31: 1 | W31: 1 | X31: 0 | Y31: 0 | AA31: =B31+G31+L31+Q31+V31 -> 38 | AB31: =(AA31+(B31/C31*D31+G31/H31*I31+L31/M31*N31+Q31/R31*S31+V31/W31*X31))/($D$1+$I$1+$N$1+$S$1+$X$1) -> 0.024558338 | AC31: =(E31+J31+O31+T31+Y31)/(AA31) -> 0.5
A32: Karma | B32: 1 | C32: 75 | D32: 137 | E32: 1 | G32: 3 | H32: 65 | I32: 56 | J32: 0 | L32: 34 | M32: 47 | N32: 37 | O32: 13 | R32: 1 | W32: 1 | AA32: =B32+G32+L32+Q32+V32 -> 38 | AB32: =(AA32+(B32/C32*D32+G32/H32*I32+L32/M32*N32+Q32/R32*S32+V32/W32*X32))/($D$1+$I$1+$N$1+$S$1+$X$1) -> 0.023593874 | AC32: =(E32+J32+O32+T32+Y32)/(AA32) -> 0.36842105
A33: Swain | B33: 24 | C33: 25 | D33: 31 | E33: 14 | G33: 3 | H33: 3 | I33: 1 | J33: 1 | L33: 1 | M33: 1 | N33: 0 | O33: 0 | Q33: 4 | R33: 4 | S33: 0 | T33: 1 | W33: 1 | AA33: =B33+G33+L33+Q33+V33 -> 32 | AB33: =(AA33+(B33/C33*D33+G33/H33*I33+L33/M33*N33+Q33/R33*S33+V33/W33*X33))/($D$1+$I$1+$N$1+$S$1+$X$1) -> 0.021405184 | AC33: =(E33+J33+O33+T33+Y33)/(AA33) -> 0.5
A34: Gragas | B34: 1 | C34: 108 | D34: 38 | E34: 0 | G34: 32 | H34: 118 | I34: 77 | J34: 14 | M34: 1 | R34: 1 | W34: 1 | AA34: =B34+G34+L34+Q34+V34 -> 33 | AB34: =(AA34+(B34/C34*D34+G34/H34*I34+L34/M34*N34+Q34/R34*S34+V34/W34*X34))/($D$1+$I$1+$N$1+$S$1+$X$1) -> 0.018497001 | AC34: =(E34+J34+O34+T34+Y34)/(AA34) -> 0.42424242
A35: K'Sante | C35: 1 | G35: 24 | H35: 269 | I35: 192 | J35: 15 | L35: 1 | M35: 279 | N35: 154 | O35: 0 | R35: 1 | W35: 1 | AA35: =B35+G35+L35+Q35+V35 -> 25 | AB35: =(AA35+(B35/C35*D35+G35/H35*I35+L35/M35*N35+Q35/R35*S35+V35/W35*X35))/($D$1+$I$1+$N$1+$S$1+$X$1) -> 0.014557327 | AC35: =(E35+J35+O35+T35+Y35)/(AA35) -> 0.6
A36: Yasou | B36: 6 | C36: 11 | D36: 7 | E36: 3 | G36: 5 | H36: 8 | I36: 6 | J36: 2 | L36: 6 | M36: 12 | N36: 17 | O36: 3 | Q36: 2 | R36: 3 | S36: 3 | T36: 0 | W36: 1 | AA36: =B36+G36+L36+Q36+V36 -> 19 | AB36: =(AA36+(B36/C36*D36+G36/H36*I36+L36/M36*N36+Q36/R36*S36+V36/W36*X36))/($D$1+$I$1+$N$1+$S$1+$X$1) -> 0.012642627 | AC36: =(E36+J36+O36+T36+Y36)/(AA36) -> 0.42105263
A37: Seraphine | B37: 11 | C37: 31 | D37: 39 | E37: 3 | G37: 1 | H37: 2 | I37: 2 | J37: 1 | L37: 1 | M37: 19 | N37: 5 | O37: 1 | R37: 1 | W37: 1 | AA37: =B37+G37+L37+Q37+V37 -> 13 | AB37: =(AA37+(B37/C37*D37+G37/H37*I37+L37/M37*N37+Q37/R37*S37+V37/W37*X37))/($D$1+$I$1+$N$1+$S$1+$X$1) -> 0.0095845387 | AC37: =(E37+J37+O37+T37+Y37)/(AA37) -> 0.38461538
A38: Nautilus | C38: 1 | G38: 14 | H38: 139 | I38: 130 | J38: 9 | M38: 1 | R38: 1 | W38: 1 | AA38: =B38+G38+L38+Q38+V38 -> 14 | AB38: =(AA38+(B38/C38*D38+G38/H38*I38+L38/M38*N38+Q38/R38*S38+V38/W38*X38))/($D$1+$I$1+$N$1+$S$1+$X$1) -> 0.0092406293 | AC38: =(E38+J38+O38+T38+Y38)/(AA38) -> 0.64285714
A39: Ziggs | C39: 1 | H39: 1 | L39: 5 | M39: 63 | N39: 89 | O39: 2 | Q39: 6 | R39: 44 | S39: 41 | T39: 4 | V39: 1 | W39: 8 | X39: 7 | Y39: 0 | AA39: =B39+G39+L39+Q39+V39 -> 12 | AB39: =(AA39+(B39/C39*D39+G39/H39*I39+L39/M39*N39+Q39/R39*S39+V39/W39*X39))/($D$1+$I$1+$N$1+$S$1+$X$1) -> 0.0087071627 | AC39: =(E39+J39+O39+T39+Y39)/(AA39) -> 0.5
A40: Zeri | C40: 1 | H40: 1 | L40: 17 | M40: 158 | N40: 60 | O40: 7 | Q40: 1 | R40: 52 | S40: 18 | T40: 0 | W40: 1 | AA40: =B40+G40+L40+Q40+V40 -> 18 | AB40: =(AA40+(B40/C40*D40+G40/H40*I40+L40/M40*N40+Q40/R40*S40+V40/W40*X40))/($D$1+$I$1+$N$1+$S$1+$X$1) -> 0.0084590212 | AC40: =(E40+J40+O40+T40+Y40)/(AA40) -> 0.38888889
...

Sheet Bottom
A1: Bottom | B1: 2022 | C1: Games: | D1: 686 | G1: 2023 | H1: Games: | I1: 688 | L1: 2024 | M1: Games: | N1: 679 | Q1: 2025 | R1: Games: | S1: 754 | V1: 2026 | W1: Games: | X1: 125
A2: Champion | B2: Picks | C2: Total | D2: Bans | E2: Wins | G2: Picks | H2: Total | I2: Bans | J2: Wins | L2: Picks | M2: Total | N2: Bans | O2: Wins | Q2: Picks | R2: Total | S2: Bans | T2: Wins | V2: Picks | W2: Total | X2: Bans | Y2: Wins | AA2: Total Picks | AB2: Pickrate | AC2: Winrate
A3: Kalista | B3: 92 | C3: 93 | D3: 252 | E3: 42 | G3: 22 | H3: 29 | I3: 61 | J3: 10 | L3: 143 | M3: 148 | N3: 338 | O3: 83 | Q3: 66 | R3: 66 | S3: 308 | T3: 31 | V3: 12 | W3: 12 | X3: 8 | Y3: 5 | AA3: =B3+G3+L3+Q3+V3 -> 335 | AB3: =(AA3+(B3/C3*D3+G3/H3*I3+L3/M3*N3+Q3/R3*S3+V3/W3*X3))/($D$1+$I$1+$N$1+$S$1+$X$1) -> 0.43422485 | AC3: =(E3+J3+O3+T3+Y3)/(AA3) -> 0.51044776
A4: Varus | B4: 35 | C4: 35 | D4: 13 | E4: 16 | G4: 129 | H4: 130 | I4: 139 | J4: 63 | L4: 131 | M4: 133 | N4: 148 | O4: 61 | Q4: 144 | R4: 145 | S4: 297 | T4: 75 | V4: 22 | W4: 22 | X4: 65 | Y4: 12 | AA4: =B4+G4+L4+Q4+V4 -> 461 | AB4: =(AA4+(B4/C4*D4+G4/H4*I4+L4/M4*N4+Q4/R4*S4+V4/W4*X4))/($D$1+$I$1+$N$1+$S$1+$X$1) -> 0.38119268 | AC4: =(E4+J4+O4+T4+Y4)/(AA4) -> 0.49240781
A5: Lucian | B5: 76 | C5: 79 | D5: 260 | E5: 39 | G5: 92 | H5: 92 | I5: 196 | J5: 49 | L5: 99 | M5: 126 | N5: 177 | O5: 55 | Q5: 100 | R5: 100 | S5: 79 | T5: 47 | V5: 20 | W5: 20 | X5: 25 | Y5: 9 | AA5: =B5+G5+L5+Q5+V5 -> 387 | AB5: =(AA5+(B5/C5*D5+G5/H5*I5+L5/M5*N5+Q5/R5*S5+V5/W5*X5))/($D$1+$I$1+$N$1+$S$1+$X$1) -> 0.36705253 | AC5: =(E5+J5+O5+T5+Y5)/(AA5) -> 0.51421189
A6: Zeri | B6: 117 | C6: 117 | D6: 249 | E6: 68 | G6: 222 | H6: 222 | I6: 93 | J6: 106 | L6: 140 | M6: 158 | N6: 60 | O6: 72 | Q6: 51 | R6: 52 | S6: 18 | T6: 26 | V6: 2 | W6: 2 | X6: 3 | Y6: 1 | AA6: =B6+G6+L6+Q6+V6 -> 532 | AB6: =(AA6+(B6/C6*D6+G6/H6*I6+L6/M6*N6+Q6/R6*S6+V6/W6*X6))/($D$1+$I$1+$N$1+$S$1+$X$1) -> 0.32326685 | AC6: =(E6+J6+O6+T6+Y6)/(AA6) -> 0.51315789
A7: Kai'Sa | B7: 77 | C7: 80 | D7: 44 | E7: 45 | G7: 163 | H7: 165 | I7: 70 | J7: 82 | L7: 91 | M7: 91 | N7: 61 | O7: 41 | Q7: 137 | R7: 137 | S7: 139 | T7: 72 | V7: 11 | W7: 11 | X7: 6 | Y7: 8 | AA7: =B7+G7+L7+Q7+V7 -> 479 | AB7: =(AA7+(B7/C7*D7+G7/H7*I7+L7/M7*N7+Q7/R7*S7+V7/W7*X7))/($D$1+$I$1+$N$1+$S$1+$X$1) -> 0.27165809 | AC7: =(E7+J7+O7+T7+Y7)/(AA7) -> 0.5177453
A8: Ezreal | B8: 94 | C8: 94 | D8: 64 | E8: 45 | G8: 58 | H8: 59 | I8: 14 | J8: 23 | L8: 124 | M8: 126 | N8: 106 | O8: 61 | Q8: 156 | R8: 156 | S8: 110 | T8: 72 | V8: 26 | W8: 26 | X8: 12 | Y8: 10 | AA8: =B8+G8+L8+Q8+V8 -> 458 | AB8: =(AA8+(B8/C8*D8+G8/H8*I8+L8/M8*N8+Q8/R8*S8+V8/W8*X8))/($D$1+$I$1+$N$1+$S$1+$X$1) -> 0.2599182 | AC8: =(E8+J8+O8+T8+Y8)/(AA8) -> 0.46069869
A9: Xayah | B9: 80 | C9: 80 | D9: 33 | E9: 41 | G9: 189 | H9: 189 | I9: 130 | J9: 105 | L9: 66 | M9: 66 | N9: 31 | O9: 25 | Q9: 98 | R9: 98 | S9: 109 | T9: 58 | V9: 6 | W9: 6 | X9: 3 | Y9: 4 | AA9: =B9+G9+L9+Q9+V9 -> 439 | AB9: =(AA9+(B9/C9*D9+G9/H9*I9+L9/M9*N9+Q9/R9*S9+V9/W9*X9))/($D$1+$I$1+$N$1+$S$1+$X$1) -> 0.25409277 | AC9: =(E9+J9+O9+T9+Y9)/(AA9) -> 0.53075171
A10: Aphelios | B10: 244 | C10: 244 | D10: 122 | E10: 120 | G10: 207 | H10: 207 | I10: 57 | J10: 99 | L10: 37 | M10: 37 | N10: 9 | O10: 17 | Q10: 10 | R10: 10 | S10: 1 | T10: 3 | V10: 20 | W10: 20 | X10: 13 | Y10: 11 | AA10: =B10+G10+L10+Q10+V10 -> 518 | AB10: =(AA10+(B10/C10*D10+G10/H10*I10+L10/M10*N10+Q10/R10*S10+V10/W10*X10))/($D$1+$I$1+$N$1+$S$1+$X$1) -> 0.24556617 | AC10: =(E10+J10+O10+T10+Y10)/(AA10) -> 0.48262548
A11: Caitlyn | B11: 43 | C11: 43 | D11: 274 | E11: 22 | G11: 41 | H11: 50 | I11: 197 | J11: 22 | L11: 23 | M11: 24 | N11: 29 | O11: 12 | Q11: 48 | R11: 48 | S11: 65 | T11: 25 | V11: 4 | W11: 4 | X11: 1 | Y11: 1 | AA11: =B11+G11+L11+Q11+V11 -> 159 | AB11: =(AA11+(B11/C11*D11+G11/H11*I11+L11/M11*N11+Q11/R11*S11+V11/W11*X11))/($D$1+$I$1+$N$1+$S$1+$X$1) -> 0.23476523 | AC11: =(E11+J11+O11+T11+Y11)/(AA11) -> 0.51572327
A12: Ashe | B12: 16 | C12: 23 | D12: 10 | E12: 8 | G12: 30 | H12: 64 | I12: 197 | J12: 11 | L12: 84 | M12: 122 | N12: 374 | O12: 47 | Q12: 69 | R12: 71 | S12: 66 | T12: 44 | V12: 11 | W12: 11 | X12: 7 | Y12: 7 | AA12: =B12+G12+L12+Q12+V12 -> 210 | AB12: =(AA12+(B12/C12*D12+G12/H12*I12+L12/M12*N12+Q12/R12*S12+V12/W12*X12))/($D$1+$I$1+$N$1+$S$1+$X$1) -> 0.21758162 | AC12: =(E12+J12+O12+T12+Y12)/(AA12) -> 0.55714286
A13: Senna | B13: 1 | C13: 51 | D13: 60 | E13: 0 | H13: 1 | L13: 100 | M13: 115 | N13: 297 | O13: 71 | Q13: 44 | R13: 45 | S13: 36 | T13: 22 | W13: 1 | AA13: =B13+G13+L13+Q13+V13 -> 145 | AB13: =(AA13+(B13/C13*D13+G13/H13*I13+L13/M13*N13+Q13/R13*S13+V13/W13*X13))/($D$1+$I$1+$N$1+$S$1+$X$1) -> 0.14994452 | AC13: =(E13+J13+O13+T13+Y13)/(AA13) -> 0.64137931
A14: Jhin | B14: 66 | C14: 66 | D14: 9 | E14: 25 | G14: 19 | H14: 24 | I14: 1 | J14: 7 | L14: 71 | M14: 71 | N14: 34 | O14: 35 | Q14: 134 | R14: 134 | S14: 52 | T14: 70 | V14: 17 | W14: 17 | X14: 4 | Y14: 8 | AA14: =B14+G14+L14+Q14+V14 -> 307 | AB14: =(AA14+(B14/C14*D14+G14/H14*I14+L14/M14*N14+Q14/R14*S14+V14/W14*X14))/($D$1+$I$1+$N$1+$S$1+$X$1) -> 0.13874204 | AC14: =(E14+J14+O14+T14+Y14)/(AA14) -> 0.4723127
A15: Jinx | B15: 163 | C15: 163 | D15: 48 | E15: 86 | G15: 74 | H15: 74 | I15: 24 | J15: 41 | L15: 24 | M15: 24 | N15: 15 | O15: 9 | Q15: 30 | R15: 30 | S15: 13 | T15: 16 | V15: 4 | W15: 4 | X15: 0 | Y15: 2 | AA15: =B15+G15+L15+Q15+V15 -> 295 | AB15: =(AA15+(B15/C15*D15+G15/H15*I15+L15/M15*N15+Q15/R15*S15+V15/W15*X15))/($D$1+$I$1+$N$1+$S$1+$X$1) -> 0.13472033 | AC15: =(E15+J15+O15+T15+Y15)/(AA15) -> 0.5220339
A16: Sivir | B16: 53 | C16: 53 | D16: 48 | E16: 35 | G16: 31 | H16: 31 | I16: 13 | J16: 15 | L16: 5 | M16: 5 | N16: 2 | O16: 0 | Q16: 80 | R16: 80 | S16: 65 | T16: 37 | V16: 16 | W16: 16 | X16: 16 | Y16: 10 | AA16: =B16+G16+L16+Q16+V16 -> 185 | AB16: =(AA16+(B16/C16*D16+G16/H16*I16+L16/M16*N16+Q16/R16*S16+V16/W16*X16))/($D$1+$I$1+$N$1+$S$1+$X$1) -> 0.1122101 | AC16: =(E16+J16+O16+T16+Y16)/(AA16) -> 0.52432432
A17: Miss Fortune | B17: 34 | C17: 34 | D17: 14 | E17: 11 | G17: 1 | H17: 1 | I17: 1 | J17: 0 | L17: 59 | M17: 59 | N17: 26 | O17: 24 | Q17: 103 | R17: 103 | S17: 75 | T17: 47 | V17: 6 | W17: 6 | X17: 4 | Y17: 2 | AA17: =B17+G17+L17+Q17+V17 -> 203 | AB17: =(AA17+(B17/C17*D17+G17/H17*I17+L17/M17*N17+Q17/R17*S17+V17/W17*X17))/($D$1+$I$1+$N$1+$S$1+$X$1) -> 0.11016371 | AC17: =(E17+J17+O17+T17+Y17)/(AA17) -> 0.4137931
A18: Draven | B18: 25 | C18: 25 | D18: 67 | E18: 14 | G18: 48 | H18: 48 | I18: 69 | J18: 26 | L18: 26 | M18: 30 | N18: 31 | O18: 8 | Q18: 15 | R18: 15 | S18: 22 | T18: 6 | W18: 1 | AA18: =B18+G18+L18+Q18+V18 -> 114 | AB18: =(AA18+(B18/C18*D18+G18/H18*I18+L18/M18*N18+Q18/R18*S18+V18/W18*X18))/($D$1+$I$1+$N$1+$S$1+$X$1) -> 0.1019327 | AC18: =(E18+J18+O18+T18+Y18)/(AA18) -> 0.47368421
A19: Yunara | C19: 1 | H19: 1 | M19: 1 | Q19: 40 | R19: 40 | S19: 155 | T19: 24 | V19: 36 | W19: 36 | X19: 30 | Y19: 19 | AA19: =B19+G19+L19+Q19+V19 -> 76 | AB19: =(AA19+(B19/C19*D19+G19/H19*I19+L19/M19*N19+Q19/R19*S19+V19/W19*X19))/($D$1+$I$1+$N$1+$S$1+$X$1) -> 0.089017735 | AC19: =(E19+J19+O19+T19+Y19)/(AA19) -> 0.56578947
A20: Ziggs | B20: 9 | C20: 9 | D20: 6 | E20: 5 | G20: 7 | H20: 7 | I20: 10 | J20: 3 | L20: 58 | M20: 63 | N20: 89 | O20: 30 | Q20: 38 | R20: 44 | S20: 41 | T20: 16 | V20: 7 | W20: 8 | X20: 7 | Y20: 2 | AA20: =B20+G20+L20+Q20+V20 -> 119 | AB20: =(AA20+(B20/C20*D20+G20/H20*I20+L20/M20*N20+Q20/R20*S20+V20/W20*X20))/($D$1+$I$1+$N$1+$S$1+$X$1) -> 0.088155047 | AC20: =(E20+J20+O20+T20+Y20)/(AA20) -> 0.47058824
A21: Corki | C21: 1 | H21: 1 | L21: 4 | M21: 202 | N21: 127 | O21: 1 | Q21: 115 | R21: 161 | S21: 64 | T21: 53 | V21: 29 | W21: 29 | X21: 13 | Y21: 14 | AA21: =B21+G21+L21+Q21+V21 -> 148 | AB21: =(AA21+(B21/C21*D21+G21/H21*I21+L21/M21*N21+Q21/R21*S21+V21/W21*X21))/($D$1+$I$1+$N$1+$S$1+$X$1) -> 0.071360552 | AC21: =(E21+J21+O21+T21+Y21)/(AA21) -> 0.45945946
A22: Tristana | B22: 36 | C22: 37 | D22: 25 | E22: 16 | G22: 12 | H22: 85 | I22: 139 | J22: 9 | L22: 3 | M22: 140 | N22: 154 | O22: 0 | Q22: 9 | R22: 24 | S22: 12 | T22: 4 | V22: 1 | W22: 3 | X22: 0 | Y22: 0 | AA22: =B22+G22+L22+Q22+V22 -> 61 | AB22: =(AA22+(B22/C22*D22+G22/H22*I22+L22/M22*N22+Q22/R22*S22+V22/W22*X22))/($D$1+$I$1+$N$1+$S$1+$X$1) -> 0.038454248 | AC22: =(E22+J22+O22+T22+Y22)/(AA22) -> 0.47540984
A23: Smolder | C23: 1 | H23: 1 | L23: 41 | M23: 73 | N23: 75 | O23: 17 | Q23: 10 | R23: 19 | S23: 10 | T23: 3 | W23: 1 | AA23: =B23+G23+L23+Q23+V23 -> 51 | AB23: =(AA23+(B23/C23*D23+G23/H23*I23+L23/M23*N23+Q23/R23*S23+V23/W23*X23))/($D$1+$I$1+$N$1+$S$1+$X$1) -> 0.033556086 | AC23: =(E23+J23+O23+T23+Y23)/(AA23) -> 0.39215686
A24: Nilah | B24: 12 | C24: 12 | D24: 7 | E24: 4 | G24: 9 | H24: 9 | I24: 15 | J24: 5 | L24: 6 | M24: 6 | N24: 6 | O24: 2 | Q24: 3 | R24: 3 | S24: 1 | T24: 2 | W24: 1 | AA24: =B24+G24+L24+Q24+V24 -> 30 | AB24: =(AA24+(B24/C24*D24+G24/H24*I24+L24/M24*N24+Q24/R24*S24+V24/W24*X24))/($D$1+$I$1+$N$1+$S$1+$X$1) -> 0.020122783 | AC24: =(E24+J24+O24+T24+Y24)/(AA24) -> 0.43333333
A25: Seraphine | B25: 17 | C25: 31 | D25: 39 | E25: 6 | H25: 1 | L25: 10 | M25: 19 | N25: 5 | O25: 4 | R25: 1 | W25: 1 | AA25: =B25+G25+L25+Q25+V25 -> 27 | AB25: =(AA25+(B25/C25*D25+G25/H25*I25+L25/M25*N25+Q25/R25*S25+V25/W25*X25))/($D$1+$I$1+$N$1+$S$1+$X$1) -> 0.01740064 | AC25: =(E25+J25+O25+T25+Y25)/(AA25) -> 0.37037037
A26: Samira | B26: 16 | C26: 16 | D26: 12 | E26: 6 | G26: 8 | H26: 8 | I26: 8 | J26: 4 | L26: 2 | M26: 2 | N26: 0 | O26: 1 | R26: 1 | W26: 1 | AA26: =B26+G26+L26+Q26+V26 -> 26 | AB26: =(AA26+(B26/C26*D26+G26/H26*I26+L26/M26*N26+Q26/R26*S26+V26/W26*X26))/($D$1+$I$1+$N$1+$S$1+$X$1) -> 0.01568895 | AC26: =(E26+J26+O26+T26+Y26)/(AA26) -> 0.42307692
A27: Tahm Kench | B27: 23 | C27: 122 | D27: 75 | E27: 10 | G27: 6 | H27: 27 | I27: 10 | J27: 4 | M27: 1 | R27: 1 | W27: 1 | AA27: =B27+G27+L27+Q27+V27 -> 29 | AB27: =(AA27+(B27/C27*D27+G27/H27*I27+L27/M27*N27+Q27/R27*S27+V27/W27*X27))/($D$1+$I$1+$N$1+$S$1+$X$1) -> 0.015471203 | AC27: =(E27+J27+O27+T27+Y27)/(AA27) -> 0.48275862
A28: Twitch | B28: 10 | C28: 10 | D28: 7 | E28: 6 | G28: 1 | H28: 3 | I28: 2 | J28: 1 | L28: 1 | M28: 1 | N28: 2 | O28: 1 | Q28: 1 | R28: 1 | S28: 1 | T28: 0 | W28: 1 | AA28: =B28+G28+L28+Q28+V28 -> 13 | AB28: =(AA28+(B28/C28*D28+G28/H28*I28+L28/M28*N28+Q28/R28*S28+V28/W28*X28))/($D$1+$I$1+$N$1+$S$1+$X$1) -> 0.0080718508 | AC28: =(E28+J28+O28+T28+Y28)/(AA28) -> 0.61538462
A29: Kog'Maw | B29: 5 | C29: 5 | D29: 2 | E29: 1 | G29: 2 | H29: 2 | I29: 1 | J29: 1 | L29: 3 | M29: 3 | N29: 0 | O29: 1 | Q29: 1 | R29: 1 | S29: 0 | T29: 0 | W29: 1 | AA29: =B29+G29+L29+Q29+V29 -> 11 | AB29: =(AA29+(B29/C29*D29+G29/H29*I29+L29/M29*N29+Q29/R29*S29+V29/W29*X29))/($D$1+$I$1+$N$1+$S$1+$X$1) -> 0.0047748977 | AC29: =(E29+J29+O29+T29+Y29)/(AA29) -> 0.27272727
A30: Vayne | B30: 4 | C30: 6 | D30: 0 | E30: 2 | G30: 3 | H30: 3 | I30: 0 | J30: 1 | L30: 1 | M30: 15 | N30: 21 | O30: 0 | Q30: 3 | R30: 4 | S30: 0 | T30: 1 | W30: 1 | AA30: =B30+G30+L30+Q30+V30 -> 11 | AB30: =(AA30+(B30/C30*D30+G30/H30*I30+L30/M30*N30+Q30/R30*S30+V30/W30*X30))/($D$1+$I$1+$N$1+$S$1+$X$1) -> 0.0042291951 | AC30: =(E30+J30+O30+T30+Y30)/(AA30) -> 0.36363636
A31: Yasou | B31: 4 | C31: 11 | D31: 7 | E31: 3 | H31: 1 | L31: 1 | M31: 12 | N31: 17 | O31: 0 | Q31: 1 | R31: 3 | S31: 3 | T31: 0 | W31: 1 | AA31: =B31+G31+L31+Q31+V31 -> 6 | AB31: =(AA31+(B31/C31*D31+G31/H31*I31+L31/M31*N31+Q31/R31*S31+V31/W31*X31))/($D$1+$I$1+$N$1+$S$1+$X$1) -> 0.0037387862 | AC31: =(E31+J31+O31+T31+Y31)/(AA31) -> 0.5
A32: Twisted Fate | C32: 1 | H32: 1 | L32: 2 | M32: 54 | N32: 107 | O32: 1 | R32: 1 | W32: 1 | AA32: =B32+G32+L32+Q32+V32 -> 2 | AB32: =(AA32+(B32/C32*D32+G32/H32*I32+L32/M32*N32+Q32/R32*S32+V32/W32*X32))/($D$1+$I$1+$N$1+$S$1+$X$1) -> 0.0020337527 | AC32: =(E32+J32+O32+T32+Y32)/(AA32) -> 0.5
A33: Singed | B33: 3 | C33: 6 | D33: 4 | E33: 2 | H33: 1 | M33: 1 | R33: 1 | W33: 1 | AA33: =B33+G33+L33+Q33+V33 -> 3 | AB33: =(AA33+(B33/C33*D33+G33/H33*I33+L33/M33*N33+Q33/R33*S33+V33/W33*X33))/($D$1+$I$1+$N$1+$S$1+$X$1) -> 0.0017053206 | AC33: =(E33+J33+O33+T33+Y33)/(AA33) -> 0.66666667
A34: Viktor | B34: 2 | C34: 108 | D34: 49 | E34: 0 | H34: 1 | M34: 1 | Q34: 1 | R34: 102 | S34: 65 | T34: 0 | W34: 1 | AA34: =B34+G34+L34+Q34+V34 -> 3 | AB34: =(AA34+(B34/C34*D34+G34/H34*I34+L34/M34*N34+Q34/R34*S34+V34/W34*X34))/($D$1+$I$1+$N$1+$S$1+$X$1) -> 0.0015500213 | AC34: =(E34+J34+O34+T34+Y34)/(AA34) -> 0
A35: Nautilus | B35: 2 | C35: 184 | D35: 144 | E35: 2 | H35: 1 | M35: 1 | R35: 1 | W35: 1 | AA35: =B35+G35+L35+Q35+V35 -> 2 | AB35: =(AA35+(B35/C35*D35+G35/H35*I35+L35/M35*N35+Q35/R35*S35+V35/W35*X35))/($D$1+$I$1+$N$1+$S$1+$X$1) -> 0.0012159677 | AC35: =(E35+J35+O35+T35+Y35)/(AA35) -> 1
A36: Heimerdinger | B36: 1 | C36: 9 | D36: 13 | E36: 0 | H36: 1 | M36: 1 | R36: 1 | W36: 1 | AA36: =B36+G36+L36+Q36+V36 -> 1 | AB36: =(AA36+(B36/C36*D36+G36/H36*I36+L36/M36*N36+Q36/R36*S36+V36/W36*X36))/($D$1+$I$1+$N$1+$S$1+$X$1) -> 0.00083371229 | AC36: =(E36+J36+O36+T36+Y36)/(AA36) -> 0
A37: Maokai | C37: 1 | G37: 1 | H37: 196 | I37: 282 | J37: 0 | M37: 1 | R37: 1 | W37: 1 | AA37: =B37+G37+L37+Q37+V37 -> 1 | AB37: =(AA37+(B37/C37*D37+G37/H37*I37+L37/M37*N37+Q37/R37*S37+V37/W37*X37))/($D$1+$I$1+$N$1+$S$1+$X$1) -> 0.00083177882 | AC37: =(E37+J37+O37+T37+Y37)/(AA37) -> 0
A38: Karthus | B38: 1 | C38: 5 | D38: 7 | E38: 0 | H38: 1 | M38: 1 | R38: 1 | W38: 1 | AA38: =B38+G38+L38+Q38+V38 -> 1 | AB38: =(AA38+(B38/C38*D38+G38/H38*I38+L38/M38*N38+Q38/R38*S38+V38/W38*X38))/($D$1+$I$1+$N$1+$S$1+$X$1) -> 0.00081855389 | AC38: =(E38+J38+O38+T38+Y38)/(AA38) -> 0
A39: Mel | C39: 1 | H39: 1 | M39: 1 | Q39: 1 | R39: 8 | S39: 9 | T39: 0 | W39: 1 | AA39: =B39+G39+L39+Q39+V39 -> 1 | AB39: =(AA39+(B39/C39*D39+G39/H39*I39+L39/M39*N39+Q39/R39*S39+V39/W39*X39))/($D$1+$I$1+$N$1+$S$1+$X$1) -> 0.00072476126 | AC39: =(E39+J39+O39+T39+Y39)/(AA39) -> 0
A40: Sion | B40: 1 | C40: 20 | D40: 2 | E40: 1 | H40: 1 | L40: 1 | M40: 7 | N40: 0 | O40: 0 | R40: 1 | W40: 1 | AA40: =B40+G40+L40+Q40+V40 -> 2 | AB40: =(AA40+(B40/C40*D40+G40/H40*I40+L40/M40*N40+Q40/R40*S40+V40/W40*X40))/($D$1+$I$1+$N$1+$S$1+$X$1) -> 0.00071623465 | AC40: =(E40+J40+O40+T40+Y40)/(AA40) -> 0.5
...

Sheet Support
A1: Support | B1: 2022 | C1: Games: | D1: 686 | G1: 2023 | H1: Games: | I1: 688 | L1: 2024 | M1: Games: | N1: 679 | Q1: 2025 | R1: Games: | S1: 754 | V1: 2026 | W1: Games: | X1: 125
A2: Champion | B2: Picks | C2: Total | D2: Bans | E2: Wins | G2: Picks | H2: Total | I2: Bans | J2: Wins | L2: Picks | M2: Total | N2: Bans | O2: Wins | Q2: Picks | R2: Total | S2: Bans | T2: Wins | V2: Picks | W2: Total | X2: Bans | Y2: Wins | AA2: Total Picks | AB2: Pickrate | AC2: Winrate
A3: Nautilus | B3: 182 | C3: 184 | D3: 144 | E3: 85 | G3: 118 | H3: 139 | I3: 130 | J3: 56 | L3: 162 | M3: 163 | N3: 165 | O3: 72 | Q3: 130 | R3: 130 | S3: 101 | T3: 55 | V3: 20 | W3: 21 | X3: 37 | Y3: 10 | AA3: =B3+G3+L3+Q3+V3 -> 612 | AB3: =(AA3+(B3/C3*D3+G3/H3*I3+L3/M3*N3+Q3/R3*S3+V3/W3*X3))/($D$1+$I$1+$N$1+$S$1+$X$1) -> 0.39734663 | AC3: =(E3+J3+O3+T3+Y3)/(AA3) -> 0.45424837
A4: Rakan | B4: 92 | C4: 92 | D4: 82 | E4: 48 | G4: 207 | H4: 207 | I4: 150 | J4: 116 | L4: 143 | M4: 143 | N4: 111 | O4: 70 | Q4: 165 | R4: 165 | S4: 167 | T4: 88 | V4: 24 | W4: 24 | X4: 9 | Y4: 15 | AA4: =B4+G4+L4+Q4+V4 -> 631 | AB4: =(AA4+(B4/C4*D4+G4/H4*I4+L4/M4*N4+Q4/R4*S4+V4/W4*X4))/($D$1+$I$1+$N$1+$S$1+$X$1) -> 0.39222374 | AC4: =(E4+J4+O4+T4+Y4)/(AA4) -> 0.5340729
A5: Alistar | B5: 44 | C5: 44 | D5: 35 | E5: 18 | G5: 96 | H5: 96 | I5: 87 | J5: 43 | L5: 130 | M5: 130 | N5: 89 | O5: 72 | Q5: 182 | R5: 182 | S5: 208 | T5: 94 | V5: 22 | W5: 22 | X5: 14 | Y5: 8 | AA5: =B5+G5+L5+Q5+V5 -> 474 | AB5: =(AA5+(B5/C5*D5+G5/H5*I5+L5/M5*N5+Q5/R5*S5+V5/W5*X5))/($D$1+$I$1+$N$1+$S$1+$X$1) -> 0.30934516 | AC5: =(E5+J5+O5+T5+Y5)/(AA5) -> 0.49578059
A6: Leona | B6: 164 | C6: 164 | D6: 72 | E6: 74 | G6: 57 | H6: 57 | I6: 12 | J6: 24 | L6: 132 | M6: 132 | N6: 107 | O6: 63 | Q6: 133 | R6: 133 | S6: 52 | T6: 61 | V6: 12 | W6: 12 | X6: 10 | Y6: 5 | AA6: =B6+G6+L6+Q6+V6 -> 498 | AB6: =(AA6+(B6/C6*D6+G6/H6*I6+L6/M6*N6+Q6/R6*S6+V6/W6*X6))/($D$1+$I$1+$N$1+$S$1+$X$1) -> 0.25613915 | AC6: =(E6+J6+O6+T6+Y6)/(AA6) -> 0.45582329
A7: Rell | B7: 27 | C7: 27 | D7: 9 | E7: 13 | G7: 111 | H7: 150 | I7: 83 | J7: 53 | L7: 169 | M7: 222 | N7: 110 | O7: 81 | Q7: 167 | R7: 167 | S7: 54 | T7: 85 | V7: 13 | W7: 13 | X7: 6 | Y7: 6 | AA7: =B7+G7+L7+Q7+V7 -> 487 | AB7: =(AA7+(B7/C7*D7+G7/H7*I7+L7/M7*N7+Q7/R7*S7+V7/W7*X7))/($D$1+$I$1+$N$1+$S$1+$X$1) -> 0.23914009 | AC7: =(E7+J7+O7+T7+Y7)/(AA7) -> 0.48870637
A8: Renata Glasc | B8: 114 | C8: 114 | D8: 123 | E8: 67 | G8: 33 | H8: 33 | I8: 49 | J8: 23 | L8: 81 | M8: 81 | N8: 99 | O8: 37 | Q8: 69 | R8: 69 | S8: 59 | T8: 30 | V8: 13 | W8: 13 | X8: 6 | Y8: 5 | AA8: =B8+G8+L8+Q8+V8 -> 310 | AB8: =(AA8+(B8/C8*D8+G8/H8*I8+L8/M8*N8+Q8/R8*S8+V8/W8*X8))/($D$1+$I$1+$N$1+$S$1+$X$1) -> 0.22032742 | AC8: =(E8+J8+O8+T8+Y8)/(AA8) -> 0.52258065
